Workbook

Sheet Reglas
B2: CONQUER · Rutina Mati y Nach
B3: Una hoja por día. Cada sesión anotás un solo número por escalón (la PEOR de las 3 series) en la columna Real. La planilla predice la siguiente y mide si acertó.
B5: Parámetros del modelo (editables)
B6: Incremento por sesión, dinámico (reps) | C6: 1
B7: Incremento por sesión, isométrico (s) | C7: 2
B8: Si el Δ medio de la hoja Modelo da más que esto varias semanas, el cuerpo progresa más rápido que la predicción: subí el incremento.
B10: Qué completás vos | C10: Celdas amarillas: progresión y modo de cada escalón (desplegables), y el número Real de cada sesión.
B11: Prev (predicción) | C11: Lo que la planilla espera que hagas esa sesión: la sesión anterior + el incremento, sin pasar del techo. Si venís de dos techos seguidos, predice el piso de la progresión siguiente.
B12: Real | C12: Lo que hiciste. Peor de las 3 series. Reps en dinámicos, segundos en isométricos y hold.
B13: Piso / techo | C13: Dinámico 3 → 8 reps. Isométrico 4 → 12 s.
B14: Subir de progresión | C14: Real = techo dos sesiones seguidas → Estado en verde: SUBIR. Elegís la progresión siguiente en el desplegable (las escaleras están en la hoja Escaleras, de más dura a más fácil) y la fila vuelve al piso.
B15: Un escalón por vez | C15: Si dos escalones dicen SUBIR, subí el E1 primero.
B16: Hold final | C16: Siempre al fallo, sin objetivo. Anotás segundos.
B17: Acierto y Δ | C17: Acierto = sesiones donde Real ≥ Prev. Δ = Real − Prev promedio. Con eso, en la hoja Modelo, ves si la predicción va corta o larga y ajustás los parámetros.
B18: Combos | C18: Hoja Combos: por cada combo anotás dos cosas por semana. Progresión de arranque: la elegís del desplegable. Series completadas: cuántas series del combo metiste en total. El objetivo gris es el plan (apertura 3, y 4 desde la semana 3).
B19: Sábado | C19: Sábado: push y después pull. Series completadas = las 3 máx más los drops que metiste, objetivo 13.
B21: Amarillo: lo completás vos
B22: Gris: predicción, no se toca
B23: Techo cumplido una vez
B24: SUBIR de progresión

Sheet Simulación
A1: CONQUER · Simulación
A2: Datos inventados para ver cómo se leen los gráficos. 12 sesiones de Planche press E1: sube de a 1, toca el techo dos veces, salta a la progresión siguiente y vuelve al piso.
B5: Sesión | C5: S1 | D5: S2 | E5: S3 | F5: S4 | G5: S5 | H5: S6 | I5: S7 | J5: S8 | K5: S9 | L5: S10 | M5: S11 | N5: S12
B6: Planche press E1 · predicho | C6: 3 | D6: 6 | E6: 7 | F6: 8 | G6: 8 | H6: 3 | I6: 4 | J6: 5 | K6: 6 | L6: 7 | M6: 8 | N6: 8
B7: Planche press E1 · real | C7: 5 | D7: 6 | E7: 7 | F7: 8 | G7: 8 | H7: 3 | I7: 4 | J7: 5 | K7: 6 | L7: 7 | M7: 8 | N7: 8
B8: Hold final (s) | C8: 9 | D8: 10 | E8: 10 | F8: 12 | G8: 11 | H8: 8 | I8: 9 | J8: 9 | K8: 11 | L8: 12 | M8: 12 | N8: 13
B9: Progresión | C9: tuck | D9: tuck | E9: tuck | F9: tuck | G9: tuck | H9: adv tuck | I9: adv tuck | J9: adv tuck | K9: adv tuck | L9: adv tuck | M9: adv tuck | N9: adv tuck
B10: Estado | C10: en rango | D10: en rango | E10: en rango | F10: techo 1 de 2 | G10: ⬆ SUBIR | H10: en rango | I10: en rango | J10: en rango | K10: en rango | L10: en rango | M10: techo 1 de 2 | N10: ⬆ SUBIR
B12: Así se van a ver los gráficos cuando haya datos reales (hoja Gráficos).

Sheet Plancha
A1: CONQUER · Rutina Mati y Nach
A2: PLANCHA
A3: Ejemplo cargado en Planche press E1 (fila 10): 6, 7, 8, 8. Borralo cuando arranques. · Amarillo = lo completás vos (progresión, modo, Real). Gris = predicción.
A4: Ejercicio | B4: Escalón | C4: Progresión | D4: Modo | E4: Tipo | F4: Piso | G4: Techo | H4: S1 prev | I4: S1 real | J4: S2 prev | K4: S2 real | L4: S3 prev | M4: S3 real | N4: S4 prev | O4: S4 real | P4: S5 prev | Q4: S5 real | R4: S6 prev | S4: S6 real | T4: Última | U4: Próximo (S7 prev) | V4: Estado | W4: Aciertos | X4: Sesiones | Y4: % acierto | Z4: Δ medio
A5: Planche hold | B5: E1 | C5: full | D5: hold | E5: s | F5: =IF(E5="reps",3,4) -> 4 | G5: =IF(E5="reps",8,12) -> 12 | H5: =F5 -> 4 | J5: =IF(I5="","",IF(FALSE(),F5,MIN(G5,I5+IF(E5="s",Reglas!$C$7,Reglas!$C$6)))) | L5: =IF(K5="","",IF(AND(K5>=G5,I5>=G5),F5,MIN(G5,K5+IF(E5="s",Reglas!$C$7,Reglas!$C$6)))) | N5: =IF(M5="","",IF(AND(M5>=G5,K5>=G5),F5,MIN(G5,M5+IF(E5="s",Reglas!$C$7,Reglas!$C$6)))) | P5: =IF(O5="","",IF(AND(O5>=G5,M5>=G5),F5,MIN(G5,O5+IF(E5="s",Reglas!$C$7,Reglas!$C$6)))) | R5: =IF(Q5="","",IF(AND(Q5>=G5,O5>=G5),F5,MIN(G5,Q5+IF(E5="s",Reglas!$C$7,Reglas!$C$6)))) | T5: =IF(S5<>"",S5,IF(Q5<>"",Q5,IF(O5<>"",O5,IF(M5<>"",M5,IF(K5<>"",K5,IF(I5<>"",I5,"")))))) | U5: =IF(B5="hold final","al fallo",IF(T5="",F5&" (piso)",IF(AND(T5>=G5,IF(AND(S5<>"",TRUE()),Q5,IF(AND(Q5<>"",S5=""),O5,IF(AND(O5<>"",Q5=""),M5,IF(AND(M5<>"",O5=""),K5,IF(AND(K5<>"",M5=""),I5,0)))))>=G5),F5&" (piso, progresión nueva)",MIN(G5,T5+IF(E5="s",Reglas!$C$7,Reglas!$C$6))))) -> 4 (piso) | V5: =IF(B5="hold final","",IF(T5="","sin datos",IF(AND(T5>=G5,IF(AND(S5<>"",TRUE()),Q5,IF(AND(Q5<>"",S5=""),O5,IF(AND(O5<>"",Q5=""),M5,IF(AND(M5<>"",O5=""),K5,IF(AND(K5<>"",M5=""),I5,0)))))>=G5),"⬆ SUBIR de progresión",IF(T5>=G5,"techo 1 de 2",IF(T5<F5,"bajo el piso: revisar","en rango"))))) -> sin datos | W5: =IF(AND(I5<>"",H5<>""),IF(I5>=H5,1,0),0)+IF(AND(K5<>"",J5<>""),IF(K5>=J5,1,0),0)+IF(AND(M5<>"",L5<>""),IF(M5>=L5,1,0),0)+IF(AND(O5<>"",N5<>""),IF(O5>=N5,1,0),0)+IF(AND(Q5<>"",P5<>""),IF(Q5>=P5,1,0),0)+IF(AND(S5<>"",R5<>""),IF(S5>=R5,1,0),0) -> 0 | X5: =IF(AND(I5<>"",H5<>""),1,0)+IF(AND(K5<>"",J5<>""),1,0)+IF(AND(M5<>"",L5<>""),1,0)+IF(AND(O5<>"",N5<>""),1,0)+IF(AND(Q5<>"",P5<>""),1,0)+IF(AND(S5<>"",R5<>""),1,0) -> 0 | Y5: =IF(X5=0,"",W5/X5) | Z5: =IF(X5=0,"",(IF(AND(I5<>"",H5<>""),I5-H5,0)+IF(AND(K5<>"",J5<>""),K5-J5,0)+IF(AND(M5<>"",L5<>""),M5-L5,0)+IF(AND(O5<>"",N5<>""),O5-N5,0)+IF(AND(Q5<>"",P5<>""),Q5-P5,0)+IF(AND(S5<>"",R5<>""),S5-R5,0))/X5)
B6: E2 | C6: straddle | D6: hold | E6: s | F6: =IF(E6="reps",3,4) -> 4 | G6: =IF(E6="reps",8,12) -> 12 | H6: =F6 -> 4 | J6: =IF(I6="","",IF(FALSE(),F6,MIN(G6,I6+IF(E6="s",Reglas!$C$7,Reglas!$C$6)))) | L6: =IF(K6="","",IF(AND(K6>=G6,I6>=G6),F6,MIN(G6,K6+IF(E6="s",Reglas!$C$7,Reglas!$C$6)))) | N6: =IF(M6="","",IF(AND(M6>=G6,K6>=G6),F6,MIN(G6,M6+IF(E6="s",Reglas!$C$7,Reglas!$C$6)))) | P6: =IF(O6="","",IF(AND(O6>=G6,M6>=G6),F6,MIN(G6,O6+IF(E6="s",Reglas!$C$7,Reglas!$C$6)))) | R6: =IF(Q6="","",IF(AND(Q6>=G6,O6>=G6),F6,MIN(G6,Q6+IF(E6="s",Reglas!$C$7,Reglas!$C$6)))) | T6: =IF(S6<>"",S6,IF(Q6<>"",Q6,IF(O6<>"",O6,IF(M6<>"",M6,IF(K6<>"",K6,IF(I6<>"",I6,"")))))) | U6: =IF(B6="hold final","al fallo",IF(T6="",F6&" (piso)",IF(AND(T6>=G6,IF(AND(S6<>"",TRUE()),Q6,IF(AND(Q6<>"",S6=""),O6,IF(AND(O6<>"",Q6=""),M6,IF(AND(M6<>"",O6=""),K6,IF(AND(K6<>"",M6=""),I6,0)))))>=G6),F6&" (piso, progresión nueva)",MIN(G6,T6+IF(E6="s",Reglas!$C$7,Reglas!$C$6))))) -> 4 (piso) | V6: =IF(B6="hold final","",IF(T6="","sin datos",IF(AND(T6>=G6,IF(AND(S6<>"",TRUE()),Q6,IF(AND(Q6<>"",S6=""),O6,IF(AND(O6<>"",Q6=""),M6,IF(AND(M6<>"",O6=""),K6,IF(AND(K6<>"",M6=""),I6,0)))))>=G6),"⬆ SUBIR de progresión",IF(T6>=G6,"techo 1 de 2",IF(T6<F6,"bajo el piso: revisar","en rango"))))) -> sin datos | W6: =IF(AND(I6<>"",H6<>""),IF(I6>=H6,1,0),0)+IF(AND(K6<>"",J6<>""),IF(K6>=J6,1,0),0)+IF(AND(M6<>"",L6<>""),IF(M6>=L6,1,0),0)+IF(AND(O6<>"",N6<>""),IF(O6>=N6,1,0),0)+IF(AND(Q6<>"",P6<>""),IF(Q6>=P6,1,0),0)+IF(AND(S6<>"",R6<>""),IF(S6>=R6,1,0),0) -> 0 | X6: =IF(AND(I6<>"",H6<>""),1,0)+IF(AND(K6<>"",J6<>""),1,0)+IF(AND(M6<>"",L6<>""),1,0)+IF(AND(O6<>"",N6<>""),1,0)+IF(AND(Q6<>"",P6<>""),1,0)+IF(AND(S6<>"",R6<>""),1,0) -> 0 | Y6: =IF(X6=0,"",W6/X6) | Z6: =IF(X6=0,"",(IF(AND(I6<>"",H6<>""),I6-H6,0)+IF(AND(K6<>"",J6<>""),K6-J6,0)+IF(AND(M6<>"",L6<>""),M6-L6,0)+IF(AND(O6<>"",N6<>""),O6-N6,0)+IF(AND(Q6<>"",P6<>""),Q6-P6,0)+IF(AND(S6<>"",R6<>""),S6-R6,0))/X6)
B7: E3 | C7: adv tuck | D7: hold | E7: s | F7: =IF(E7="reps",3,4) -> 4 | G7: =IF(E7="reps",8,12) -> 12 | H7: =F7 -> 4 | J7: =IF(I7="","",IF(FALSE(),F7,MIN(G7,I7+IF(E7="s",Reglas!$C$7,Reglas!$C$6)))) | L7: =IF(K7="","",IF(AND(K7>=G7,I7>=G7),F7,MIN(G7,K7+IF(E7="s",Reglas!$C$7,Reglas!$C$6)))) | N7: =IF(M7="","",IF(AND(M7>=G7,K7>=G7),F7,MIN(G7,M7+IF(E7="s",Reglas!$C$7,Reglas!$C$6)))) | P7: =IF(O7="","",IF(AND(O7>=G7,M7>=G7),F7,MIN(G7,O7+IF(E7="s",Reglas!$C$7,Reglas!$C$6)))) | R7: =IF(Q7="","",IF(AND(Q7>=G7,O7>=G7),F7,MIN(G7,Q7+IF(E7="s",Reglas!$C$7,Reglas!$C$6)))) | T7: =IF(S7<>"",S7,IF(Q7<>"",Q7,IF(O7<>"",O7,IF(M7<>"",M7,IF(K7<>"",K7,IF(I7<>"",I7,"")))))) | U7: =IF(B7="hold final","al fallo",IF(T7="",F7&" (piso)",IF(AND(T7>=G7,IF(AND(S7<>"",TRUE()),Q7,IF(AND(Q7<>"",S7=""),O7,IF(AND(O7<>"",Q7=""),M7,IF(AND(M7<>"",O7=""),K7,IF(AND(K7<>"",M7=""),I7,0)))))>=G7),F7&" (piso, progresión nueva)",MIN(G7,T7+IF(E7="s",Reglas!$C$7,Reglas!$C$6))))) -> 4 (piso) | V7: =IF(B7="hold final","",IF(T7="","sin datos",IF(AND(T7>=G7,IF(AND(S7<>"",TRUE()),Q7,IF(AND(Q7<>"",S7=""),O7,IF(AND(O7<>"",Q7=""),M7,IF(AND(M7<>"",O7=""),K7,IF(AND(K7<>"",M7=""),I7,0)))))>=G7),"⬆ SUBIR de progresión",IF(T7>=G7,"techo 1 de 2",IF(T7<F7,"bajo el piso: revisar","en rango"))))) -> sin datos | W7: =IF(AND(I7<>"",H7<>""),IF(I7>=H7,1,0),0)+IF(AND(K7<>"",J7<>""),IF(K7>=J7,1,0),0)+IF(AND(M7<>"",L7<>""),IF(M7>=L7,1,0),0)+IF(AND(O7<>"",N7<>""),IF(O7>=N7,1,0),0)+IF(AND(Q7<>"",P7<>""),IF(Q7>=P7,1,0),0)+IF(AND(S7<>"",R7<>""),IF(S7>=R7,1,0),0) -> 0 | X7: =IF(AND(I7<>"",H7<>""),1,0)+IF(AND(K7<>"",J7<>""),1,0)+IF(AND(M7<>"",L7<>""),1,0)+IF(AND(O7<>"",N7<>""),1,0)+IF(AND(Q7<>"",P7<>""),1,0)+IF(AND(S7<>"",R7<>""),1,0) -> 0 | Y7: =IF(X7=0,"",W7/X7) | Z7: =IF(X7=0,"",(IF(AND(I7<>"",H7<>""),I7-H7,0)+IF(AND(K7<>"",J7<>""),K7-J7,0)+IF(AND(M7<>"",L7<>""),M7-L7,0)+IF(AND(O7<>"",N7<>""),O7-N7,0)+IF(AND(Q7<>"",P7<>""),Q7-P7,0)+IF(AND(S7<>"",R7<>""),S7-R7,0))/X7)
B8: hold final | C8: tuck | D8: hold | E8: s | F8: =IF(E8="reps",3,4) -> 4 | G8: =IF(E8="reps",8,12) -> 12 | H8: al fallo | J8: al fallo | L8: al fallo | N8: al fallo | P8: al fallo | R8: al fallo | T8: =IF(S8<>"",S8,IF(Q8<>"",Q8,IF(O8<>"",O8,IF(M8<>"",M8,IF(K8<>"",K8,IF(I8<>"",I8,"")))))) | U8: =IF(B8="hold final","al fallo",IF(T8="",F8&" (piso)",IF(AND(T8>=G8,IF(AND(S8<>"",TRUE()),Q8,IF(AND(Q8<>"",S8=""),O8,IF(AND(O8<>"",Q8=""),M8,IF(AND(M8<>"",O8=""),K8,IF(AND(K8<>"",M8=""),I8,0)))))>=G8),F8&" (piso, progresión nueva)",MIN(G8,T8+IF(E8="s",Reglas!$C$7,Reglas!$C$6))))) -> al fallo | V8: =IF(B8="hold final","",IF(T8="","sin datos",IF(AND(T8>=G8,IF(AND(S8<>"",TRUE()),Q8,IF(AND(Q8<>"",S8=""),O8,IF(AND(O8<>"",Q8=""),M8,IF(AND(M8<>"",O8=""),K8,IF(AND(K8<>"",M8=""),I8,0)))))>=G8),"⬆ SUBIR de progresión",IF(T8>=G8,"techo 1 de 2",IF(T8<F8,"bajo el piso: revisar","en rango")))))
A10: Planche press | B10: E1 | C10: tuck | D10: completa | E10: reps | F10: =IF(E10="reps",3,4) -> 3 | G10: =IF(E10="reps",8,12) -> 8 | H10: =F10 -> 3 | I10: 6 | J10: =IF(I10="","",IF(FALSE(),F10,MIN(G10,I10+IF(E10="s",Reglas!$C$7,Reglas!$C$6)))) -> 7 | K10: 7 | L10: =IF(K10="","",IF(AND(K10>=G10,I10>=G10),F10,MIN(G10,K10+IF(E10="s",Reglas!$C$7,Reglas!$C$6)))) -> 8 | M10: 8 | N10: =IF(M10="","",IF(AND(M10>=G10,K10>=G10),F10,MIN(G10,M10+IF(E10="s",Reglas!$C$7,Reglas!$C$6)))) -> 8 | O10: 8 | P10: =IF(O10="","",IF(AND(O10>=G10,M10>=G10),F10,MIN(G10,O10+IF(E10="s",Reglas!$C$7,Reglas!$C$6)))) -> 3 | R10: =IF(Q10="","",IF(AND(Q10>=G10,O10>=G10),F10,MIN(G10,Q10+IF(E10="s",Reglas!$C$7,Reglas!$C$6)))) | T10: =IF(S10<>"",S10,IF(Q10<>"",Q10,IF(O10<>"",O10,IF(M10<>"",M10,IF(K10<>"",K10,IF(I10<>"",I10,"")))))) -> 8 | U10: =IF(B10="hold final","al fallo",IF(T10="",F10&" (piso)",IF(AND(T10>=G10,IF(AND(S10<>"",TRUE()),Q10,IF(AND(Q10<>"",S10=""),O10,IF(AND(O10<>"",Q10=""),M10,IF(AND(M10<>"",O10=""),K10,IF(AND(K10<>"",M10=""),I10,0)))))>=G10),F10&" (piso, progresión nueva)",MIN(G10,T10+IF(E10="s",Reglas!$C$7,Reglas!$C$6))))) -> 3 (piso, progresión nueva) | V10: =IF(B10="hold final","",IF(T10="","sin datos",IF(AND(T10>=G10,IF(AND(S10<>"",TRUE()),Q10,IF(AND(Q10<>"",S10=""),O10,IF(AND(O10<>"",Q10=""),M10,IF(AND(M10<>"",O10=""),K10,IF(AND(K10<>"",M10=""),I10,0)))))>=G10),"⬆ SUBIR de progresión",IF(T10>=G10,"techo 1 de 2",IF(T10<F10,"bajo el piso: revisar","en rango"))))) -> ⬆ SUBIR de progresión | W10: =IF(AND(I10<>"",H10<>""),IF(I10>=H10,1,0),0)+IF(AND(K10<>"",J10<>""),IF(K10>=J10,1,0),0)+IF(AND(M10<>"",L10<>""),IF(M10>=L10,1,0),0)+IF(AND(O10<>"",N10<>""),IF(O10>=N10,1,0),0)+IF(AND(Q10<>"",P10<>""),IF(Q10>=P10,1,0),0)+IF(AND(S10<>"",R10<>""),IF(S10>=R10,1,0),0) -> 4 | X10: =IF(AND(I10<>"",H10<>""),1,0)+IF(AND(K10<>"",J10<>""),1,0)+IF(AND(M10<>"",L10<>""),1,0)+IF(AND(O10<>"",N10<>""),1,0)+IF(AND(Q10<>"",P10<>""),1,0)+IF(AND(S10<>"",R10<>""),1,0) -> 4 | Y10: =IF(X10=0,"",W10/X10) -> 1 | Z10: =IF(X10=0,"",(IF(AND(I10<>"",H10<>""),I10-H10,0)+IF(AND(K10<>"",J10<>""),K10-J10,0)+IF(AND(M10<>"",L10<>""),M10-L10,0)+IF(AND(O10<>"",N10<>""),O10-N10,0)+IF(AND(Q10<>"",P10<>""),Q10-P10,0)+IF(AND(S10<>"",R10<>""),S10-R10,0))/X10) -> 0.75
B11: E2 | C11: tuck | D11: negativa | E11: reps | F11: =IF(E11="reps",3,4) -> 3 | G11: =IF(E11="reps",8,12) -> 8 | H11: =F11 -> 3 | J11: =IF(I11="","",IF(FALSE(),F11,MIN(G11,I11+IF(E11="s",Reglas!$C$7,Reglas!$C$6)))) | L11: =IF(K11="","",IF(AND(K11>=G11,I11>=G11),F11,MIN(G11,K11+IF(E11="s",Reglas!$C$7,Reglas!$C$6)))) | N11: =IF(M11="","",IF(AND(M11>=G11,K11>=G11),F11,MIN(G11,M11+IF(E11="s",Reglas!$C$7,Reglas!$C$6)))) | P11: =IF(O11="","",IF(AND(O11>=G11,M11>=G11),F11,MIN(G11,O11+IF(E11="s",Reglas!$C$7,Reglas!$C$6)))) | R11: =IF(Q11="","",IF(AND(Q11>=G11,O11>=G11),F11,MIN(G11,Q11+IF(E11="s",Reglas!$C$7,Reglas!$C$6)))) | T11: =IF(S11<>"",S11,IF(Q11<>"",Q11,IF(O11<>"",O11,IF(M11<>"",M11,IF(K11<>"",K11,IF(I11<>"",I11,"")))))) | U11: =IF(B11="hold final","al fallo",IF(T11="",F11&" (piso)",IF(AND(T11>=G11,IF(AND(S11<>"",TRUE()),Q11,IF(AND(Q11<>"",S11=""),O11,IF(AND(O11<>"",Q11=""),M11,IF(AND(M11<>"",O11=""),K11,IF(AND(K11<>"",M11=""),I11,0)))))>=G11),F11&" (piso, progresión nueva)",MIN(G11,T11+IF(E11="s",Reglas!$C$7,Reglas!$C$6))))) -> 3 (piso) | V11: =IF(B11="hold final","",IF(T11="","sin datos",IF(AND(T11>=G11,IF(AND(S11<>"",TRUE()),Q11,IF(AND(Q11<>"",S11=""),O11,IF(AND(O11<>"",Q11=""),M11,IF(AND(M11<>"",O11=""),K11,IF(AND(K11<>"",M11=""),I11,0)))))>=G11),"⬆ SUBIR de progresión",IF(T11>=G11,"techo 1 de 2",IF(T11<F11,"bajo el piso: revisar","en rango"))))) -> sin datos | W11: =IF(AND(I11<>"",H11<>""),IF(I11>=H11,1,0),0)+IF(AND(K11<>"",J11<>""),IF(K11>=J11,1,0),0)+IF(AND(M11<>"",L11<>""),IF(M11>=L11,1,0),0)+IF(AND(O11<>"",N11<>""),IF(O11>=N11,1,0),0)+IF(AND(Q11<>"",P11<>""),IF(Q11>=P11,1,0),0)+IF(AND(S11<>"",R11<>""),IF(S11>=R11,1,0),0) -> 0 | X11: =IF(AND(I11<>"",H11<>""),1,0)+IF(AND(K11<>"",J11<>""),1,0)+IF(AND(M11<>"",L11<>""),1,0)+IF(AND(O11<>"",N11<>""),1,0)+IF(AND(Q11<>"",P11<>""),1,0)+IF(AND(S11<>"",R11<>""),1,0) -> 0 | Y11: =IF(X11=0,"",W11/X11) | Z11: =IF(X11=0,"",(IF(AND(I11<>"",H11<>""),I11-H11,0)+IF(AND(K11<>"",J11<>""),K11-J11,0)+IF(AND(M11<>"",L11<>""),M11-L11,0)+IF(AND(O11<>"",N11<>""),O11-N11,0)+IF(AND(Q11<>"",P11<>""),Q11-P11,0)+IF(AND(S11<>"",R11<>""),S11-R11,0))/X11)
B12: E3 | C12: lean | D12: completa | E12: reps | F12: =IF(E12="reps",3,4) -> 3 | G12: =IF(E12="reps",8,12) -> 8 | H12: =F12 -> 3 | J12: =IF(I12="","",IF(FALSE(),F12,MIN(G12,I12+IF(E12="s",Reglas!$C$7,Reglas!$C$6)))) | L12: =IF(K12="","",IF(AND(K12>=G12,I12>=G12),F12,MIN(G12,K12+IF(E12="s",Reglas!$C$7,Reglas!$C$6)))) | N12: =IF(M12="","",IF(AND(M12>=G12,K12>=G12),F12,MIN(G12,M12+IF(E12="s",Reglas!$C$7,Reglas!$C$6)))) | P12: =IF(O12="","",IF(AND(O12>=G12,M12>=G12),F12,MIN(G12,O12+IF(E12="s",Reglas!$C$7,Reglas!$C$6)))) | R12: =IF(Q12="","",IF(AND(Q12>=G12,O12>=G12),F12,MIN(G12,Q12+IF(E12="s",Reglas!$C$7,Reglas!$C$6)))) | T12: =IF(S12<>"",S12,IF(Q12<>"",Q12,IF(O12<>"",O12,IF(M12<>"",M12,IF(K12<>"",K12,IF(I12<>"",I12,"")))))) | U12: =IF(B12="hold final","al fallo",IF(T12="",F12&" (piso)",IF(AND(T12>=G12,IF(AND(S12<>"",TRUE()),Q12,IF(AND(Q12<>"",S12=""),O12,IF(AND(O12<>"",Q12=""),M12,IF(AND(M12<>"",O12=""),K12,IF(AND(K12<>"",M12=""),I12,0)))))>=G12),F12&" (piso, progresión nueva)",MIN(G12,T12+IF(E12="s",Reglas!$C$7,Reglas!$C$6))))) -> 3 (piso) | V12: =IF(B12="hold final","",IF(T12="","sin datos",IF(AND(T12>=G12,IF(AND(S12<>"",TRUE()),Q12,IF(AND(Q12<>"",S12=""),O12,IF(AND(O12<>"",Q12=""),M12,IF(AND(M12<>"",O12=""),K12,IF(AND(K12<>"",M12=""),I12,0)))))>=G12),"⬆ SUBIR de progresión",IF(T12>=G12,"techo 1 de 2",IF(T12<F12,"bajo el piso: revisar","en rango"))))) -> sin datos | W12: =IF(AND(I12<>"",H12<>""),IF(I12>=H12,1,0),0)+IF(AND(K12<>"",J12<>""),IF(K12>=J12,1,0),0)+IF(AND(M12<>"",L12<>""),IF(M12>=L12,1,0),0)+IF(AND(O12<>"",N12<>""),IF(O12>=N12,1,0),0)+IF(AND(Q12<>"",P12<>""),IF(Q12>=P12,1,0),0)+IF(AND(S12<>"",R12<>""),IF(S12>=R12,1,0),0) -> 0 | X12: =IF(AND(I12<>"",H12<>""),1,0)+IF(AND(K12<>"",J12<>""),1,0)+IF(AND(M12<>"",L12<>""),1,0)+IF(AND(O12<>"",N12<>""),1,0)+IF(AND(Q12<>"",P12<>""),1,0)+IF(AND(S12<>"",R12<>""),1,0) -> 0 | Y12: =IF(X12=0,"",W12/X12) | Z12: =IF(X12=0,"",(IF(AND(I12<>"",H12<>""),I12-H12,0)+IF(AND(K12<>"",J12<>""),K12-J12,0)+IF(AND(M12<>"",L12<>""),M12-L12,0)+IF(AND(O12<>"",N12<>""),O12-N12,0)+IF(AND(Q12<>"",P12<>""),Q12-P12,0)+IF(AND(S12<>"",R12<>""),S12-R12,0))/X12)
B13: hold final | C13: lean | D13: hold | E13: s | F13: =IF(E13="reps",3,4) -> 4 | G13: =IF(E13="reps",8,12) -> 12 | H13: al fallo | J13: al fallo | L13: al fallo | N13: al fallo | P13: al fallo | R13: al fallo | T13: =IF(S13<>"",S13,IF(Q13<>"",Q13,IF(O13<>"",O13,IF(M13<>"",M13,IF(K13<>"",K13,IF(I13<>"",I13,"")))))) | U13: =IF(B13="hold final","al fallo",IF(T13="",F13&" (piso)",IF(AND(T13>=G13,IF(AND(S13<>"",TRUE()),Q13,IF(AND(Q13<>"",S13=""),O13,IF(AND(O13<>"",Q13=""),M13,IF(AND(M13<>"",O13=""),K13,IF(AND(K13<>"",M13=""),I13,0)))))>=G13),F13&" (piso, progresión nueva)",MIN(G13,T13+IF(E13="s",Reglas!$C$7,Reglas!$C$6))))) -> al fallo | V13: =IF(B13="hold final","",IF(T13="","sin datos",IF(AND(T13>=G13,IF(AND(S13<>"",TRUE()),Q13,IF(AND(Q13<>"",S13=""),O13,IF(AND(O13<>"",Q13=""),M13,IF(AND(M13<>"",O13=""),K13,IF(AND(K13<>"",M13=""),I13,0)))))>=G13),"⬆ SUBIR de progresión",IF(T13>=G13,"techo 1 de 2",IF(T13<F13,"bajo el piso: revisar","en rango")))))
A15: L-sit a plancha | B15: E1 | C15: a tuck | D15: completa | E15: reps | F15: =IF(E15="reps",3,4) -> 3 | G15: =IF(E15="reps",8,12) -> 8 | H15: =F15 -> 3 | J15: =IF(I15="","",IF(FALSE(),F15,MIN(G15,I15+IF(E15="s",Reglas!$C$7,Reglas!$C$6)))) | L15: =IF(K15="","",IF(AND(K15>=G15,I15>=G15),F15,MIN(G15,K15+IF(E15="s",Reglas!$C$7,Reglas!$C$6)))) | N15: =IF(M15="","",IF(AND(M15>=G15,K15>=G15),F15,MIN(G15,M15+IF(E15="s",Reglas!$C$7,Reglas!$C$6)))) | P15: =IF(O15="","",IF(AND(O15>=G15,M15>=G15),F15,MIN(G15,O15+IF(E15="s",Reglas!$C$7,Reglas!$C$6)))) | R15: =IF(Q15="","",IF(AND(Q15>=G15,O15>=G15),F15,MIN(G15,Q15+IF(E15="s",Reglas!$C$7,Reglas!$C$6)))) | T15: =IF(S15<>"",S15,IF(Q15<>"",Q15,IF(O15<>"",O15,IF(M15<>"",M15,IF(K15<>"",K15,IF(I15<>"",I15,"")))))) | U15: =IF(B15="hold final","al fallo",IF(T15="",F15&" (piso)",IF(AND(T15>=G15,IF(AND(S15<>"",TRUE()),Q15,IF(AND(Q15<>"",S15=""),O15,IF(AND(O15<>"",Q15=""),M15,IF(AND(M15<>"",O15=""),K15,IF(AND(K15<>"",M15=""),I15,0)))))>=G15),F15&" (piso, progresión nueva)",MIN(G15,T15+IF(E15="s",Reglas!$C$7,Reglas!$C$6))))) -> 3 (piso) | V15: =IF(B15="hold final","",IF(T15="","sin datos",IF(AND(T15>=G15,IF(AND(S15<>"",TRUE()),Q15,IF(AND(Q15<>"",S15=""),O15,IF(AND(O15<>"",Q15=""),M15,IF(AND(M15<>"",O15=""),K15,IF(AND(K15<>"",M15=""),I15,0)))))>=G15),"⬆ SUBIR de progresión",IF(T15>=G15,"techo 1 de 2",IF(T15<F15,"bajo el piso: revisar","en rango"))))) -> sin datos | W15: =IF(AND(I15<>"",H15<>""),IF(I15>=H15,1,0),0)+IF(AND(K15<>"",J15<>""),IF(K15>=J15,1,0),0)+IF(AND(M15<>"",L15<>""),IF(M15>=L15,1,0),0)+IF(AND(O15<>"",N15<>""),IF(O15>=N15,1,0),0)+IF(AND(Q15<>"",P15<>""),IF(Q15>=P15,1,0),0)+IF(AND(S15<>"",R15<>""),IF(S15>=R15,1,0),0) -> 0 | X15: =IF(AND(I15<>"",H15<>""),1,0)+IF(AND(K15<>"",J15<>""),1,0)+IF(AND(M15<>"",L15<>""),1,0)+IF(AND(O15<>"",N15<>""),1,0)+IF(AND(Q15<>"",P15<>""),1,0)+IF(AND(S15<>"",R15<>""),1,0) -> 0 | Y15: =IF(X15=0,"",W15/X15) | Z15: =IF(X15=0,"",(IF(AND(I15<>"",H15<>""),I15-H15,0)+IF(AND(K15<>"",J15<>""),K15-J15,0)+IF(AND(M15<>"",L15<>""),M15-L15,0)+IF(AND(O15<>"",N15<>""),O15-N15,0)+IF(AND(Q15<>"",P15<>""),Q15-P15,0)+IF(AND(S15<>"",R15<>""),S15-R15,0))/X15)
B16: E2 | C16: a tuck | D16: negativa | E16: reps | F16: =IF(E16="reps",3,4) -> 3 | G16: =IF(E16="reps",8,12) -> 8 | H16: =F16 -> 3 | J16: =IF(I16="","",IF(FALSE(),F16,MIN(G16,I16+IF(E16="s",Reglas!$C$7,Reglas!$C$6)))) | L16: =IF(K16="","",IF(AND(K16>=G16,I16>=G16),F16,MIN(G16,K16+IF(E16="s",Reglas!$C$7,Reglas!$C$6)))) | N16: =IF(M16="","",IF(AND(M16>=G16,K16>=G16),F16,MIN(G16,M16+IF(E16="s",Reglas!$C$7,Reglas!$C$6)))) | P16: =IF(O16="","",IF(AND(O16>=G16,M16>=G16),F16,MIN(G16,O16+IF(E16="s",Reglas!$C$7,Reglas!$C$6)))) | R16: =IF(Q16="","",IF(AND(Q16>=G16,O16>=G16),F16,MIN(G16,Q16+IF(E16="s",Reglas!$C$7,Reglas!$C$6)))) | T16: =IF(S16<>"",S16,IF(Q16<>"",Q16,IF(O16<>"",O16,IF(M16<>"",M16,IF(K16<>"",K16,IF(I16<>"",I16,"")))))) | U16: =IF(B16="hold final","al fallo",IF(T16="",F16&" (piso)",IF(AND(T16>=G16,IF(AND(S16<>"",TRUE()),Q16,IF(AND(Q16<>"",S16=""),O16,IF(AND(O16<>"",Q16=""),M16,IF(AND(M16<>"",O16=""),K16,IF(AND(K16<>"",M16=""),I16,0)))))>=G16),F16&" (piso, progresión nueva)",MIN(G16,T16+IF(E16="s",Reglas!$C$7,Reglas!$C$6))))) -> 3 (piso) | V16: =IF(B16="hold final","",IF(T16="","sin datos",IF(AND(T16>=G16,IF(AND(S16<>"",TRUE()),Q16,IF(AND(Q16<>"",S16=""),O16,IF(AND(O16<>"",Q16=""),M16,IF(AND(M16<>"",O16=""),K16,IF(AND(K16<>"",M16=""),I16,0)))))>=G16),"⬆ SUBIR de progresión",IF(T16>=G16,"techo 1 de 2",IF(T16<F16,"bajo el piso: revisar","en rango"))))) -> sin datos | W16: =IF(AND(I16<>"",H16<>""),IF(I16>=H16,1,0),0)+IF(AND(K16<>"",J16<>""),IF(K16>=J16,1,0),0)+IF(AND(M16<>"",L16<>""),IF(M16>=L16,1,0),0)+IF(AND(O16<>"",N16<>""),IF(O16>=N16,1,0),0)+IF(AND(Q16<>"",P16<>""),IF(Q16>=P16,1,0),0)+IF(AND(S16<>"",R16<>""),IF(S16>=R16,1,0),0) -> 0 | X16: =IF(AND(I16<>"",H16<>""),1,0)+IF(AND(K16<>"",J16<>""),1,0)+IF(AND(M16<>"",L16<>""),1,0)+IF(AND(O16<>"",N16<>""),1,0)+IF(AND(Q16<>"",P16<>""),1,0)+IF(AND(S16<>"",R16<>""),1,0) -> 0 | Y16: =IF(X16=0,"",W16/X16) | Z16: =IF(X16=0,"",(IF(AND(I16<>"",H16<>""),I16-H16,0)+IF(AND(K16<>"",J16<>""),K16-J16,0)+IF(AND(M16<>"",L16<>""),M16-L16,0)+IF(AND(O16<>"",N16<>""),O16-N16,0)+IF(AND(Q16<>"",P16<>""),Q16-P16,0)+IF(AND(S16<>"",R16<>""),S16-R16,0))/X16)
B17: E3 | C17: a lean | D17: completa | E17: reps | F17: =IF(E17="reps",3,4) -> 3 | G17: =IF(E17="reps",8,12) -> 8 | H17: =F17 -> 3 | J17: =IF(I17="","",IF(FALSE(),F17,MIN(G17,I17+IF(E17="s",Reglas!$C$7,Reglas!$C$6)))) | L17: =IF(K17="","",IF(AND(K17>=G17,I17>=G17),F17,MIN(G17,K17+IF(E17="s",Reglas!$C$7,Reglas!$C$6)))) | N17: =IF(M17="","",IF(AND(M17>=G17,K17>=G17),F17,MIN(G17,M17+IF(E17="s",Reglas!$C$7,Reglas!$C$6)))) | P17: =IF(O17="","",IF(AND(O17>=G17,M17>=G17),F17,MIN(G17,O17+IF(E17="s",Reglas!$C$7,Reglas!$C$6)))) | R17: =IF(Q17="","",IF(AND(Q17>=G17,O17>=G17),F17,MIN(G17,Q17+IF(E17="s",Reglas!$C$7,Reglas!$C$6)))) | T17: =IF(S17<>"",S17,IF(Q17<>"",Q17,IF(O17<>"",O17,IF(M17<>"",M17,IF(K17<>"",K17,IF(I17<>"",I17,"")))))) | U17: =IF(B17="hold final","al fallo",IF(T17="",F17&" (piso)",IF(AND(T17>=G17,IF(AND(S17<>"",TRUE()),Q17,IF(AND(Q17<>"",S17=""),O17,IF(AND(O17<>"",Q17=""),M17,IF(AND(M17<>"",O17=""),K17,IF(AND(K17<>"",M17=""),I17,0)))))>=G17),F17&" (piso, progresión nueva)",MIN(G17,T17+IF(E17="s",Reglas!$C$7,Reglas!$C$6))))) -> 3 (piso) | V17: =IF(B17="hold final","",IF(T17="","sin datos",IF(AND(T17>=G17,IF(AND(S17<>"",TRUE()),Q17,IF(AND(Q17<>"",S17=""),O17,IF(AND(O17<>"",Q17=""),M17,IF(AND(M17<>"",O17=""),K17,IF(AND(K17<>"",M17=""),I17,0)))))>=G17),"⬆ SUBIR de progresión",IF(T17>=G17,"techo 1 de 2",IF(T17<F17,"bajo el piso: revisar","en rango"))))) -> sin datos | W17: =IF(AND(I17<>"",H17<>""),IF(I17>=H17,1,0),0)+IF(AND(K17<>"",J17<>""),IF(K17>=J17,1,0),0)+IF(AND(M17<>"",L17<>""),IF(M17>=L17,1,0),0)+IF(AND(O17<>"",N17<>""),IF(O17>=N17,1,0),0)+IF(AND(Q17<>"",P17<>""),IF(Q17>=P17,1,0),0)+IF(AND(S17<>"",R17<>""),IF(S17>=R17,1,0),0) -> 0 | X17: =IF(AND(I17<>"",H17<>""),1,0)+IF(AND(K17<>"",J17<>""),1,0)+IF(AND(M17<>"",L17<>""),1,0)+IF(AND(O17<>"",N17<>""),1,0)+IF(AND(Q17<>"",P17<>""),1,0)+IF(AND(S17<>"",R17<>""),1,0) -> 0 | Y17: =IF(X17=0,"",W17/X17) | Z17: =IF(X17=0,"",(IF(AND(I17<>"",H17<>""),I17-H17,0)+IF(AND(K17<>"",J17<>""),K17-J17,0)+IF(AND(M17<>"",L17<>""),M17-L17,0)+IF(AND(O17<>"",N17<>""),O17-N17,0)+IF(AND(Q17<>"",P17<>""),Q17-P17,0)+IF(AND(S17<>"",R17<>""),S17-R17,0))/X17)
B18: hold final | C18: a tuck | D18: hold | E18: s | F18: =IF(E18="reps",3,4) -> 4 | G18: =IF(E18="reps",8,12) -> 12 | H18: al fallo | J18: al fallo | L18: al fallo | N18: al fallo | P18: al fallo | R18: al fallo | T18: =IF(S18<>"",S18,IF(Q18<>"",Q18,IF(O18<>"",O18,IF(M18<>"",M18,IF(K18<>"",K18,IF(I18<>"",I18,"")))))) | U18: =IF(B18="hold final","al fallo",IF(T18="",F18&" (piso)",IF(AND(T18>=G18,IF(AND(S18<>"",TRUE()),Q18,IF(AND(Q18<>"",S18=""),O18,IF(AND(O18<>"",Q18=""),M18,IF(AND(M18<>"",O18=""),K18,IF(AND(K18<>"",M18=""),I18,0)))))>=G18),F18&" (piso, progresión nueva)",MIN(G18,T18+IF(E18="s",Reglas!$C$7,Reglas!$C$6))))) -> al fallo | V18: =IF(B18="hold final","",IF(T18="","sin datos",IF(AND(T18>=G18,IF(AND(S18<>"",TRUE()),Q18,IF(AND(Q18<>"",S18=""),O18,IF(AND(O18<>"",Q18=""),M18,IF(AND(M18<>"",O18=""),K18,IF(AND(K18<>"",M18=""),I18,0)))))>=G18),"⬆ SUBIR de progresión",IF(T18>=G18,"techo 1 de 2",IF(T18<F18,"bajo el piso: revisar","en rango")))))

Sheet Front
A1: CONQUER · Rutina Mati y Nach
A2: FRONT
A3: · Amarillo = lo completás vos (progresión, modo, Real). Gris = predicción.
A4: Ejercicio | B4: Escalón | C4: Progresión | D4: Modo | E4: Tipo | F4: Piso | G4: Techo | H4: S1 prev | I4: S1 real | J4: S2 prev | K4: S2 real | L4: S3 prev | M4: S3 real | N4: S4 prev | O4: S4 real | P4: S5 prev | Q4: S5 real | R4: S6 prev | S4: S6 real | T4: Última | U4: Próximo (S7 prev) | V4: Estado | W4: Aciertos | X4: Sesiones | Y4: % acierto | Z4: Δ medio
A5: Front lever hold | B5: E1 | C5: full | D5: hold | E5: s | F5: =IF(E5="reps",3,4) -> 4 | G5: =IF(E5="reps",8,12) -> 12 | H5: =F5 -> 4 | J5: =IF(I5="","",IF(FALSE(),F5,MIN(G5,I5+IF(E5="s",Reglas!$C$7,Reglas!$C$6)))) | L5: =IF(K5="","",IF(AND(K5>=G5,I5>=G5),F5,MIN(G5,K5+IF(E5="s",Reglas!$C$7,Reglas!$C$6)))) | N5: =IF(M5="","",IF(AND(M5>=G5,K5>=G5),F5,MIN(G5,M5+IF(E5="s",Reglas!$C$7,Reglas!$C$6)))) | P5: =IF(O5="","",IF(AND(O5>=G5,M5>=G5),F5,MIN(G5,O5+IF(E5="s",Reglas!$C$7,Reglas!$C$6)))) | R5: =IF(Q5="","",IF(AND(Q5>=G5,O5>=G5),F5,MIN(G5,Q5+IF(E5="s",Reglas!$C$7,Reglas!$C$6)))) | T5: =IF(S5<>"",S5,IF(Q5<>"",Q5,IF(O5<>"",O5,IF(M5<>"",M5,IF(K5<>"",K5,IF(I5<>"",I5,"")))))) | U5: =IF(B5="hold final","al fallo",IF(T5="",F5&" (piso)",IF(AND(T5>=G5,IF(AND(S5<>"",TRUE()),Q5,IF(AND(Q5<>"",S5=""),O5,IF(AND(O5<>"",Q5=""),M5,IF(AND(M5<>"",O5=""),K5,IF(AND(K5<>"",M5=""),I5,0)))))>=G5),F5&" (piso, progresión nueva)",MIN(G5,T5+IF(E5="s",Reglas!$C$7,Reglas!$C$6))))) -> 4 (piso) | V5: =IF(B5="hold final","",IF(T5="","sin datos",IF(AND(T5>=G5,IF(AND(S5<>"",TRUE()),Q5,IF(AND(Q5<>"",S5=""),O5,IF(AND(O5<>"",Q5=""),M5,IF(AND(M5<>"",O5=""),K5,IF(AND(K5<>"",M5=""),I5,0)))))>=G5),"⬆ SUBIR de progresión",IF(T5>=G5,"techo 1 de 2",IF(T5<F5,"bajo el piso: revisar","en rango"))))) -> sin datos | W5: =IF(AND(I5<>"",H5<>""),IF(I5>=H5,1,0),0)+IF(AND(K5<>"",J5<>""),IF(K5>=J5,1,0),0)+IF(AND(M5<>"",L5<>""),IF(M5>=L5,1,0),0)+IF(AND(O5<>"",N5<>""),IF(O5>=N5,1,0),0)+IF(AND(Q5<>"",P5<>""),IF(Q5>=P5,1,0),0)+IF(AND(S5<>"",R5<>""),IF(S5>=R5,1,0),0) -> 0 | X5: =IF(AND(I5<>"",H5<>""),1,0)+IF(AND(K5<>"",J5<>""),1,0)+IF(AND(M5<>"",L5<>""),1,0)+IF(AND(O5<>"",N5<>""),1,0)+IF(AND(Q5<>"",P5<>""),1,0)+IF(AND(S5<>"",R5<>""),1,0) -> 0 | Y5: =IF(X5=0,"",W5/X5) | Z5: =IF(X5=0,"",(IF(AND(I5<>"",H5<>""),I5-H5,0)+IF(AND(K5<>"",J5<>""),K5-J5,0)+IF(AND(M5<>"",L5<>""),M5-L5,0)+IF(AND(O5<>"",N5<>""),O5-N5,0)+IF(AND(Q5<>"",P5<>""),Q5-P5,0)+IF(AND(S5<>"",R5<>""),S5-R5,0))/X5)
B6: E2 | C6: straddle | D6: hold | E6: s | F6: =IF(E6="reps",3,4) -> 4 | G6: =IF(E6="reps",8,12) -> 12 | H6: =F6 -> 4 | J6: =IF(I6="","",IF(FALSE(),F6,MIN(G6,I6+IF(E6="s",Reglas!$C$7,Reglas!$C$6)))) | L6: =IF(K6="","",IF(AND(K6>=G6,I6>=G6),F6,MIN(G6,K6+IF(E6="s",Reglas!$C$7,Reglas!$C$6)))) | N6: =IF(M6="","",IF(AND(M6>=G6,K6>=G6),F6,MIN(G6,M6+IF(E6="s",Reglas!$C$7,Reglas!$C$6)))) | P6: =IF(O6="","",IF(AND(O6>=G6,M6>=G6),F6,MIN(G6,O6+IF(E6="s",Reglas!$C$7,Reglas!$C$6)))) | R6: =IF(Q6="","",IF(AND(Q6>=G6,O6>=G6),F6,MIN(G6,Q6+IF(E6="s",Reglas!$C$7,Reglas!$C$6)))) | T6: =IF(S6<>"",S6,IF(Q6<>"",Q6,IF(O6<>"",O6,IF(M6<>"",M6,IF(K6<>"",K6,IF(I6<>"",I6,"")))))) | U6: =IF(B6="hold final","al fallo",IF(T6="",F6&" (piso)",IF(AND(T6>=G6,IF(AND(S6<>"",TRUE()),Q6,IF(AND(Q6<>"",S6=""),O6,IF(AND(O6<>"",Q6=""),M6,IF(AND(M6<>"",O6=""),K6,IF(AND(K6<>"",M6=""),I6,0)))))>=G6),F6&" (piso, progresión nueva)",MIN(G6,T6+IF(E6="s",Reglas!$C$7,Reglas!$C$6))))) -> 4 (piso) | V6: =IF(B6="hold final","",IF(T6="","sin datos",IF(AND(T6>=G6,IF(AND(S6<>"",TRUE()),Q6,IF(AND(Q6<>"",S6=""),O6,IF(AND(O6<>"",Q6=""),M6,IF(AND(M6<>"",O6=""),K6,IF(AND(K6<>"",M6=""),I6,0)))))>=G6),"⬆ SUBIR de progresión",IF(T6>=G6,"techo 1 de 2",IF(T6<F6,"bajo el piso: revisar","en rango"))))) -> sin datos | W6: =IF(AND(I6<>"",H6<>""),IF(I6>=H6,1,0),0)+IF(AND(K6<>"",J6<>""),IF(K6>=J6,1,0),0)+IF(AND(M6<>"",L6<>""),IF(M6>=L6,1,0),0)+IF(AND(O6<>"",N6<>""),IF(O6>=N6,1,0),0)+IF(AND(Q6<>"",P6<>""),IF(Q6>=P6,1,0),0)+IF(AND(S6<>"",R6<>""),IF(S6>=R6,1,0),0) -> 0 | X6: =IF(AND(I6<>"",H6<>""),1,0)+IF(AND(K6<>"",J6<>""),1,0)+IF(AND(M6<>"",L6<>""),1,0)+IF(AND(O6<>"",N6<>""),1,0)+IF(AND(Q6<>"",P6<>""),1,0)+IF(AND(S6<>"",R6<>""),1,0) -> 0 | Y6: =IF(X6=0,"",W6/X6) | Z6: =IF(X6=0,"",(IF(AND(I6<>"",H6<>""),I6-H6,0)+IF(AND(K6<>"",J6<>""),K6-J6,0)+IF(AND(M6<>"",L6<>""),M6-L6,0)+IF(AND(O6<>"",N6<>""),O6-N6,0)+IF(AND(Q6<>"",P6<>""),Q6-P6,0)+IF(AND(S6<>"",R6<>""),S6-R6,0))/X6)
B7: E3 | C7: adv tuck | D7: hold | E7: s | F7: =IF(E7="reps",3,4) -> 4 | G7: =IF(E7="reps",8,12) -> 12 | H7: =F7 -> 4 | J7: =IF(I7="","",IF(FALSE(),F7,MIN(G7,I7+IF(E7="s",Reglas!$C$7,Reglas!$C$6)))) | L7: =IF(K7="","",IF(AND(K7>=G7,I7>=G7),F7,MIN(G7,K7+IF(E7="s",Reglas!$C$7,Reglas!$C$6)))) | N7: =IF(M7="","",IF(AND(M7>=G7,K7>=G7),F7,MIN(G7,M7+IF(E7="s",Reglas!$C$7,Reglas!$C$6)))) | P7: =IF(O7="","",IF(AND(O7>=G7,M7>=G7),F7,MIN(G7,O7+IF(E7="s",Reglas!$C$7,Reglas!$C$6)))) | R7: =IF(Q7="","",IF(AND(Q7>=G7,O7>=G7),F7,MIN(G7,Q7+IF(E7="s",Reglas!$C$7,Reglas!$C$6)))) | T7: =IF(S7<>"",S7,IF(Q7<>"",Q7,IF(O7<>"",O7,IF(M7<>"",M7,IF(K7<>"",K7,IF(I7<>"",I7,"")))))) | U7: =IF(B7="hold final","al fallo",IF(T7="",F7&" (piso)",IF(AND(T7>=G7,IF(AND(S7<>"",TRUE()),Q7,IF(AND(Q7<>"",S7=""),O7,IF(AND(O7<>"",Q7=""),M7,IF(AND(M7<>"",O7=""),K7,IF(AND(K7<>"",M7=""),I7,0)))))>=G7),F7&" (piso, progresión nueva)",MIN(G7,T7+IF(E7="s",Reglas!$C$7,Reglas!$C$6))))) -> 4 (piso) | V7: =IF(B7="hold final","",IF(T7="","sin datos",IF(AND(T7>=G7,IF(AND(S7<>"",TRUE()),Q7,IF(AND(Q7<>"",S7=""),O7,IF(AND(O7<>"",Q7=""),M7,IF(AND(M7<>"",O7=""),K7,IF(AND(K7<>"",M7=""),I7,0)))))>=G7),"⬆ SUBIR de progresión",IF(T7>=G7,"techo 1 de 2",IF(T7<F7,"bajo el piso: revisar","en rango"))))) -> sin datos | W7: =IF(AND(I7<>"",H7<>""),IF(I7>=H7,1,0),0)+IF(AND(K7<>"",J7<>""),IF(K7>=J7,1,0),0)+IF(AND(M7<>"",L7<>""),IF(M7>=L7,1,0),0)+IF(AND(O7<>"",N7<>""),IF(O7>=N7,1,0),0)+IF(AND(Q7<>"",P7<>""),IF(Q7>=P7,1,0),0)+IF(AND(S7<>"",R7<>""),IF(S7>=R7,1,0),0) -> 0 | X7: =IF(AND(I7<>"",H7<>""),1,0)+IF(AND(K7<>"",J7<>""),1,0)+IF(AND(M7<>"",L7<>""),1,0)+IF(AND(O7<>"",N7<>""),1,0)+IF(AND(Q7<>"",P7<>""),1,0)+IF(AND(S7<>"",R7<>""),1,0) -> 0 | Y7: =IF(X7=0,"",W7/X7) | Z7: =IF(X7=0,"",(IF(AND(I7<>"",H7<>""),I7-H7,0)+IF(AND(K7<>"",J7<>""),K7-J7,0)+IF(AND(M7<>"",L7<>""),M7-L7,0)+IF(AND(O7<>"",N7<>""),O7-N7,0)+IF(AND(Q7<>"",P7<>""),Q7-P7,0)+IF(AND(S7<>"",R7<>""),S7-R7,0))/X7)
B8: hold final | C8: tuck | D8: hold | E8: s | F8: =IF(E8="reps",3,4) -> 4 | G8: =IF(E8="reps",8,12) -> 12 | H8: al fallo | J8: al fallo | L8: al fallo | N8: al fallo | P8: al fallo | R8: al fallo | T8: =IF(S8<>"",S8,IF(Q8<>"",Q8,IF(O8<>"",O8,IF(M8<>"",M8,IF(K8<>"",K8,IF(I8<>"",I8,"")))))) | U8: =IF(B8="hold final","al fallo",IF(T8="",F8&" (piso)",IF(AND(T8>=G8,IF(AND(S8<>"",TRUE()),Q8,IF(AND(Q8<>"",S8=""),O8,IF(AND(O8<>"",Q8=""),M8,IF(AND(M8<>"",O8=""),K8,IF(AND(K8<>"",M8=""),I8,0)))))>=G8),F8&" (piso, progresión nueva)",MIN(G8,T8+IF(E8="s",Reglas!$C$7,Reglas!$C$6))))) -> al fallo | V8: =IF(B8="hold final","",IF(T8="","sin datos",IF(AND(T8>=G8,IF(AND(S8<>"",TRUE()),Q8,IF(AND(Q8<>"",S8=""),O8,IF(AND(O8<>"",Q8=""),M8,IF(AND(M8<>"",O8=""),K8,IF(AND(K8<>"",M8=""),I8,0)))))>=G8),"⬆ SUBIR de progresión",IF(T8>=G8,"techo 1 de 2",IF(T8<F8,"bajo el piso: revisar","en rango")))))
A10: Pull-ups en FL | B10: E1 | C10: adv tuck | D10: completa | E10: reps | F10: =IF(E10="reps",3,4) -> 3 | G10: =IF(E10="reps",8,12) -> 8 | H10: =F10 -> 3 | J10: =IF(I10="","",IF(FALSE(),F10,MIN(G10,I10+IF(E10="s",Reglas!$C$7,Reglas!$C$6)))) | L10: =IF(K10="","",IF(AND(K10>=G10,I10>=G10),F10,MIN(G10,K10+IF(E10="s",Reglas!$C$7,Reglas!$C$6)))) | N10: =IF(M10="","",IF(AND(M10>=G10,K10>=G10),F10,MIN(G10,M10+IF(E10="s",Reglas!$C$7,Reglas!$C$6)))) | P10: =IF(O10="","",IF(AND(O10>=G10,M10>=G10),F10,MIN(G10,O10+IF(E10="s",Reglas!$C$7,Reglas!$C$6)))) | R10: =IF(Q10="","",IF(AND(Q10>=G10,O10>=G10),F10,MIN(G10,Q10+IF(E10="s",Reglas!$C$7,Reglas!$C$6)))) | T10: =IF(S10<>"",S10,IF(Q10<>"",Q10,IF(O10<>"",O10,IF(M10<>"",M10,IF(K10<>"",K10,IF(I10<>"",I10,"")))))) | U10: =IF(B10="hold final","al fallo",IF(T10="",F10&" (piso)",IF(AND(T10>=G10,IF(AND(S10<>"",TRUE()),Q10,IF(AND(Q10<>"",S10=""),O10,IF(AND(O10<>"",Q10=""),M10,IF(AND(M10<>"",O10=""),K10,IF(AND(K10<>"",M10=""),I10,0)))))>=G10),F10&" (piso, progresión nueva)",MIN(G10,T10+IF(E10="s",Reglas!$C$7,Reglas!$C$6))))) -> 3 (piso) | V10: =IF(B10="hold final","",IF(T10="","sin datos",IF(AND(T10>=G10,IF(AND(S10<>"",TRUE()),Q10,IF(AND(Q10<>"",S10=""),O10,IF(AND(O10<>"",Q10=""),M10,IF(AND(M10<>"",O10=""),K10,IF(AND(K10<>"",M10=""),I10,0)))))>=G10),"⬆ SUBIR de progresión",IF(T10>=G10,"techo 1 de 2",IF(T10<F10,"bajo el piso: revisar","en rango"))))) -> sin datos | W10: =IF(AND(I10<>"",H10<>""),IF(I10>=H10,1,0),0)+IF(AND(K10<>"",J10<>""),IF(K10>=J10,1,0),0)+IF(AND(M10<>"",L10<>""),IF(M10>=L10,1,0),0)+IF(AND(O10<>"",N10<>""),IF(O10>=N10,1,0),0)+IF(AND(Q10<>"",P10<>""),IF(Q10>=P10,1,0),0)+IF(AND(S10<>"",R10<>""),IF(S10>=R10,1,0),0) -> 0 | X10: =IF(AND(I10<>"",H10<>""),1,0)+IF(AND(K10<>"",J10<>""),1,0)+IF(AND(M10<>"",L10<>""),1,0)+IF(AND(O10<>"",N10<>""),1,0)+IF(AND(Q10<>"",P10<>""),1,0)+IF(AND(S10<>"",R10<>""),1,0) -> 0 | Y10: =IF(X10=0,"",W10/X10) | Z10: =IF(X10=0,"",(IF(AND(I10<>"",H10<>""),I10-H10,0)+IF(AND(K10<>"",J10<>""),K10-J10,0)+IF(AND(M10<>"",L10<>""),M10-L10,0)+IF(AND(O10<>"",N10<>""),O10-N10,0)+IF(AND(Q10<>"",P10<>""),Q10-P10,0)+IF(AND(S10<>"",R10<>""),S10-R10,0))/X10)
B11: E2 | C11: adv tuck | D11: negativa | E11: reps | F11: =IF(E11="reps",3,4) -> 3 | G11: =IF(E11="reps",8,12) -> 8 | H11: =F11 -> 3 | J11: =IF(I11="","",IF(FALSE(),F11,MIN(G11,I11+IF(E11="s",Reglas!$C$7,Reglas!$C$6)))) | L11: =IF(K11="","",IF(AND(K11>=G11,I11>=G11),F11,MIN(G11,K11+IF(E11="s",Reglas!$C$7,Reglas!$C$6)))) | N11: =IF(M11="","",IF(AND(M11>=G11,K11>=G11),F11,MIN(G11,M11+IF(E11="s",Reglas!$C$7,Reglas!$C$6)))) | P11: =IF(O11="","",IF(AND(O11>=G11,M11>=G11),F11,MIN(G11,O11+IF(E11="s",Reglas!$C$7,Reglas!$C$6)))) | R11: =IF(Q11="","",IF(AND(Q11>=G11,O11>=G11),F11,MIN(G11,Q11+IF(E11="s",Reglas!$C$7,Reglas!$C$6)))) | T11: =IF(S11<>"",S11,IF(Q11<>"",Q11,IF(O11<>"",O11,IF(M11<>"",M11,IF(K11<>"",K11,IF(I11<>"",I11,"")))))) | U11: =IF(B11="hold final","al fallo",IF(T11="",F11&" (piso)",IF(AND(T11>=G11,IF(AND(S11<>"",TRUE()),Q11,IF(AND(Q11<>"",S11=""),O11,IF(AND(O11<>"",Q11=""),M11,IF(AND(M11<>"",O11=""),K11,IF(AND(K11<>"",M11=""),I11,0)))))>=G11),F11&" (piso, progresión nueva)",MIN(G11,T11+IF(E11="s",Reglas!$C$7,Reglas!$C$6))))) -> 3 (piso) | V11: =IF(B11="hold final","",IF(T11="","sin datos",IF(AND(T11>=G11,IF(AND(S11<>"",TRUE()),Q11,IF(AND(Q11<>"",S11=""),O11,IF(AND(O11<>"",Q11=""),M11,IF(AND(M11<>"",O11=""),K11,IF(AND(K11<>"",M11=""),I11,0)))))>=G11),"⬆ SUBIR de progresión",IF(T11>=G11,"techo 1 de 2",IF(T11<F11,"bajo el piso: revisar","en rango"))))) -> sin datos | W11: =IF(AND(I11<>"",H11<>""),IF(I11>=H11,1,0),0)+IF(AND(K11<>"",J11<>""),IF(K11>=J11,1,0),0)+IF(AND(M11<>"",L11<>""),IF(M11>=L11,1,0),0)+IF(AND(O11<>"",N11<>""),IF(O11>=N11,1,0),0)+IF(AND(Q11<>"",P11<>""),IF(Q11>=P11,1,0),0)+IF(AND(S11<>"",R11<>""),IF(S11>=R11,1,0),0) -> 0 | X11: =IF(AND(I11<>"",H11<>""),1,0)+IF(AND(K11<>"",J11<>""),1,0)+IF(AND(M11<>"",L11<>""),1,0)+IF(AND(O11<>"",N11<>""),1,0)+IF(AND(Q11<>"",P11<>""),1,0)+IF(AND(S11<>"",R11<>""),1,0) -> 0 | Y11: =IF(X11=0,"",W11/X11) | Z11: =IF(X11=0,"",(IF(AND(I11<>"",H11<>""),I11-H11,0)+IF(AND(K11<>"",J11<>""),K11-J11,0)+IF(AND(M11<>"",L11<>""),M11-L11,0)+IF(AND(O11<>"",N11<>""),O11-N11,0)+IF(AND(Q11<>"",P11<>""),Q11-P11,0)+IF(AND(S11<>"",R11<>""),S11-R11,0))/X11)
B12: E3 | C12: tuck | D12: completa | E12: reps | F12: =IF(E12="reps",3,4) -> 3 | G12: =IF(E12="reps",8,12) -> 8 | H12: =F12 -> 3 | J12: =IF(I12="","",IF(FALSE(),F12,MIN(G12,I12+IF(E12="s",Reglas!$C$7,Reglas!$C$6)))) | L12: =IF(K12="","",IF(AND(K12>=G12,I12>=G12),F12,MIN(G12,K12+IF(E12="s",Reglas!$C$7,Reglas!$C$6)))) | N12: =IF(M12="","",IF(AND(M12>=G12,K12>=G12),F12,MIN(G12,M12+IF(E12="s",Reglas!$C$7,Reglas!$C$6)))) | P12: =IF(O12="","",IF(AND(O12>=G12,M12>=G12),F12,MIN(G12,O12+IF(E12="s",Reglas!$C$7,Reglas!$C$6)))) | R12: =IF(Q12="","",IF(AND(Q12>=G12,O12>=G12),F12,MIN(G12,Q12+IF(E12="s",Reglas!$C$7,Reglas!$C$6)))) | T12: =IF(S12<>"",S12,IF(Q12<>"",Q12,IF(O12<>"",O12,IF(M12<>"",M12,IF(K12<>"",K12,IF(I12<>"",I12,"")))))) | U12: =IF(B12="hold final","al fallo",IF(T12="",F12&" (piso)",IF(AND(T12>=G12,IF(AND(S12<>"",TRUE()),Q12,IF(AND(Q12<>"",S12=""),O12,IF(AND(O12<>"",Q12=""),M12,IF(AND(M12<>"",O12=""),K12,IF(AND(K12<>"",M12=""),I12,0)))))>=G12),F12&" (piso, progresión nueva)",MIN(G12,T12+IF(E12="s",Reglas!$C$7,Reglas!$C$6))))) -> 3 (piso) | V12: =IF(B12="hold final","",IF(T12="","sin datos",IF(AND(T12>=G12,IF(AND(S12<>"",TRUE()),Q12,IF(AND(Q12<>"",S12=""),O12,IF(AND(O12<>"",Q12=""),M12,IF(AND(M12<>"",O12=""),K12,IF(AND(K12<>"",M12=""),I12,0)))))>=G12),"⬆ SUBIR de progresión",IF(T12>=G12,"techo 1 de 2",IF(T12<F12,"bajo el piso: revisar","en rango"))))) -> sin datos | W12: =IF(AND(I12<>"",H12<>""),IF(I12>=H12,1,0),0)+IF(AND(K12<>"",J12<>""),IF(K12>=J12,1,0),0)+IF(AND(M12<>"",L12<>""),IF(M12>=L12,1,0),0)+IF(AND(O12<>"",N12<>""),IF(O12>=N12,1,0),0)+IF(AND(Q12<>"",P12<>""),IF(Q12>=P12,1,0),0)+IF(AND(S12<>"",R12<>""),IF(S12>=R12,1,0),0) -> 0 | X12: =IF(AND(I12<>"",H12<>""),1,0)+IF(AND(K12<>"",J12<>""),1,0)+IF(AND(M12<>"",L12<>""),1,0)+IF(AND(O12<>"",N12<>""),1,0)+IF(AND(Q12<>"",P12<>""),1,0)+IF(AND(S12<>"",R12<>""),1,0) -> 0 | Y12: =IF(X12=0,"",W12/X12) | Z12: =IF(X12=0,"",(IF(AND(I12<>"",H12<>""),I12-H12,0)+IF(AND(K12<>"",J12<>""),K12-J12,0)+IF(AND(M12<>"",L12<>""),M12-L12,0)+IF(AND(O12<>"",N12<>""),O12-N12,0)+IF(AND(Q12<>"",P12<>""),Q12-P12,0)+IF(AND(S12<>"",R12<>""),S12-R12,0))/X12)
B13: hold final | C13: tuck | D13: hold | E13: s | F13: =IF(E13="reps",3,4) -> 4 | G13: =IF(E13="reps",8,12) -> 12 | H13: al fallo | J13: al fallo | L13: al fallo | N13: al fallo | P13: al fallo | R13: al fallo | T13: =IF(S13<>"",S13,IF(Q13<>"",Q13,IF(O13<>"",O13,IF(M13<>"",M13,IF(K13<>"",K13,IF(I13<>"",I13,"")))))) | U13: =IF(B13="hold final","al fallo",IF(T13="",F13&" (piso)",IF(AND(T13>=G13,IF(AND(S13<>"",TRUE()),Q13,IF(AND(Q13<>"",S13=""),O13,IF(AND(O13<>"",Q13=""),M13,IF(AND(M13<>"",O13=""),K13,IF(AND(K13<>"",M13=""),I13,0)))))>=G13),F13&" (piso, progresión nueva)",MIN(G13,T13+IF(E13="s",Reglas!$C$7,Reglas!$C$6))))) -> al fallo | V13: =IF(B13="hold final","",IF(T13="","sin datos",IF(AND(T13>=G13,IF(AND(S13<>"",TRUE()),Q13,IF(AND(Q13<>"",S13=""),O13,IF(AND(O13<>"",Q13=""),M13,IF(AND(M13<>"",O13=""),K13,IF(AND(K13<>"",M13=""),I13,0)))))>=G13),"⬆ SUBIR de progresión",IF(T13>=G13,"techo 1 de 2",IF(T13<F13,"bajo el piso: revisar","en rango")))))
A15: FL raises | B15: E1 | C15: straddle | D15: completa | E15: reps | F15: =IF(E15="reps",3,4) -> 3 | G15: =IF(E15="reps",8,12) -> 8 | H15: =F15 -> 3 | J15: =IF(I15="","",IF(FALSE(),F15,MIN(G15,I15+IF(E15="s",Reglas!$C$7,Reglas!$C$6)))) | L15: =IF(K15="","",IF(AND(K15>=G15,I15>=G15),F15,MIN(G15,K15+IF(E15="s",Reglas!$C$7,Reglas!$C$6)))) | N15: =IF(M15="","",IF(AND(M15>=G15,K15>=G15),F15,MIN(G15,M15+IF(E15="s",Reglas!$C$7,Reglas!$C$6)))) | P15: =IF(O15="","",IF(AND(O15>=G15,M15>=G15),F15,MIN(G15,O15+IF(E15="s",Reglas!$C$7,Reglas!$C$6)))) | R15: =IF(Q15="","",IF(AND(Q15>=G15,O15>=G15),F15,MIN(G15,Q15+IF(E15="s",Reglas!$C$7,Reglas!$C$6)))) | T15: =IF(S15<>"",S15,IF(Q15<>"",Q15,IF(O15<>"",O15,IF(M15<>"",M15,IF(K15<>"",K15,IF(I15<>"",I15,"")))))) | U15: =IF(B15="hold final","al fallo",IF(T15="",F15&" (piso)",IF(AND(T15>=G15,IF(AND(S15<>"",TRUE()),Q15,IF(AND(Q15<>"",S15=""),O15,IF(AND(O15<>"",Q15=""),M15,IF(AND(M15<>"",O15=""),K15,IF(AND(K15<>"",M15=""),I15,0)))))>=G15),F15&" (piso, progresión nueva)",MIN(G15,T15+IF(E15="s",Reglas!$C$7,Reglas!$C$6))))) -> 3 (piso) | V15: =IF(B15="hold final","",IF(T15="","sin datos",IF(AND(T15>=G15,IF(AND(S15<>"",TRUE()),Q15,IF(AND(Q15<>"",S15=""),O15,IF(AND(O15<>"",Q15=""),M15,IF(AND(M15<>"",O15=""),K15,IF(AND(K15<>"",M15=""),I15,0)))))>=G15),"⬆ SUBIR de progresión",IF(T15>=G15,"techo 1 de 2",IF(T15<F15,"bajo el piso: revisar","en rango"))))) -> sin datos | W15: =IF(AND(I15<>"",H15<>""),IF(I15>=H15,1,0),0)+IF(AND(K15<>"",J15<>""),IF(K15>=J15,1,0),0)+IF(AND(M15<>"",L15<>""),IF(M15>=L15,1,0),0)+IF(AND(O15<>"",N15<>""),IF(O15>=N15,1,0),0)+IF(AND(Q15<>"",P15<>""),IF(Q15>=P15,1,0),0)+IF(AND(S15<>"",R15<>""),IF(S15>=R15,1,0),0) -> 0 | X15: =IF(AND(I15<>"",H15<>""),1,0)+IF(AND(K15<>"",J15<>""),1,0)+IF(AND(M15<>"",L15<>""),1,0)+IF(AND(O15<>"",N15<>""),1,0)+IF(AND(Q15<>"",P15<>""),1,0)+IF(AND(S15<>"",R15<>""),1,0) -> 0 | Y15: =IF(X15=0,"",W15/X15) | Z15: =IF(X15=0,"",(IF(AND(I15<>"",H15<>""),I15-H15,0)+IF(AND(K15<>"",J15<>""),K15-J15,0)+IF(AND(M15<>"",L15<>""),M15-L15,0)+IF(AND(O15<>"",N15<>""),O15-N15,0)+IF(AND(Q15<>"",P15<>""),Q15-P15,0)+IF(AND(S15<>"",R15<>""),S15-R15,0))/X15)
B16: E2 | C16: straddle | D16: negativa | E16: reps | F16: =IF(E16="reps",3,4) -> 3 | G16: =IF(E16="reps",8,12) -> 8 | H16: =F16 -> 3 | J16: =IF(I16="","",IF(FALSE(),F16,MIN(G16,I16+IF(E16="s",Reglas!$C$7,Reglas!$C$6)))) | L16: =IF(K16="","",IF(AND(K16>=G16,I16>=G16),F16,MIN(G16,K16+IF(E16="s",Reglas!$C$7,Reglas!$C$6)))) | N16: =IF(M16="","",IF(AND(M16>=G16,K16>=G16),F16,MIN(G16,M16+IF(E16="s",Reglas!$C$7,Reglas!$C$6)))) | P16: =IF(O16="","",IF(AND(O16>=G16,M16>=G16),F16,MIN(G16,O16+IF(E16="s",Reglas!$C$7,Reglas!$C$6)))) | R16: =IF(Q16="","",IF(AND(Q16>=G16,O16>=G16),F16,MIN(G16,Q16+IF(E16="s",Reglas!$C$7,Reglas!$C$6)))) | T16: =IF(S16<>"",S16,IF(Q16<>"",Q16,IF(O16<>"",O16,IF(M16<>"",M16,IF(K16<>"",K16,IF(I16<>"",I16,"")))))) | U16: =IF(B16="hold final","al fallo",IF(T16="",F16&" (piso)",IF(AND(T16>=G16,IF(AND(S16<>"",TRUE()),Q16,IF(AND(Q16<>"",S16=""),O16,IF(AND(O16<>"",Q16=""),M16,IF(AND(M16<>"",O16=""),K16,IF(AND(K16<>"",M16=""),I16,0)))))>=G16),F16&" (piso, progresión nueva)",MIN(G16,T16+IF(E16="s",Reglas!$C$7,Reglas!$C$6))))) -> 3 (piso) | V16: =IF(B16="hold final","",IF(T16="","sin datos",IF(AND(T16>=G16,IF(AND(S16<>"",TRUE()),Q16,IF(AND(Q16<>"",S16=""),O16,IF(AND(O16<>"",Q16=""),M16,IF(AND(M16<>"",O16=""),K16,IF(AND(K16<>"",M16=""),I16,0)))))>=G16),"⬆ SUBIR de progresión",IF(T16>=G16,"techo 1 de 2",IF(T16<F16,"bajo el piso: revisar","en rango"))))) -> sin datos | W16: =IF(AND(I16<>"",H16<>""),IF(I16>=H16,1,0),0)+IF(AND(K16<>"",J16<>""),IF(K16>=J16,1,0),0)+IF(AND(M16<>"",L16<>""),IF(M16>=L16,1,0),0)+IF(AND(O16<>"",N16<>""),IF(O16>=N16,1,0),0)+IF(AND(Q16<>"",P16<>""),IF(Q16>=P16,1,0),0)+IF(AND(S16<>"",R16<>""),IF(S16>=R16,1,0),0) -> 0 | X16: =IF(AND(I16<>"",H16<>""),1,0)+IF(AND(K16<>"",J16<>""),1,0)+IF(AND(M16<>"",L16<>""),1,0)+IF(AND(O16<>"",N16<>""),1,0)+IF(AND(Q16<>"",P16<>""),1,0)+IF(AND(S16<>"",R16<>""),1,0) -> 0 | Y16: =IF(X16=0,"",W16/X16) | Z16: =IF(X16=0,"",(IF(AND(I16<>"",H16<>""),I16-H16,0)+IF(AND(K16<>"",J16<>""),K16-J16,0)+IF(AND(M16<>"",L16<>""),M16-L16,0)+IF(AND(O16<>"",N16<>""),O16-N16,0)+IF(AND(Q16<>"",P16<>""),Q16-P16,0)+IF(AND(S16<>"",R16<>""),S16-R16,0))/X16)
B17: E3 | C17: tuck | D17: completa | E17: reps | F17: =IF(E17="reps",3,4) -> 3 | G17: =IF(E17="reps",8,12) -> 8 | H17: =F17 -> 3 | J17: =IF(I17="","",IF(FALSE(),F17,MIN(G17,I17+IF(E17="s",Reglas!$C$7,Reglas!$C$6)))) | L17: =IF(K17="","",IF(AND(K17>=G17,I17>=G17),F17,MIN(G17,K17+IF(E17="s",Reglas!$C$7,Reglas!$C$6)))) | N17: =IF(M17="","",IF(AND(M17>=G17,K17>=G17),F17,MIN(G17,M17+IF(E17="s",Reglas!$C$7,Reglas!$C$6)))) | P17: =IF(O17="","",IF(AND(O17>=G17,M17>=G17),F17,MIN(G17,O17+IF(E17="s",Reglas!$C$7,Reglas!$C$6)))) | R17: =IF(Q17="","",IF(AND(Q17>=G17,O17>=G17),F17,MIN(G17,Q17+IF(E17="s",Reglas!$C$7,Reglas!$C$6)))) | T17: =IF(S17<>"",S17,IF(Q17<>"",Q17,IF(O17<>"",O17,IF(M17<>"",M17,IF(K17<>"",K17,IF(I17<>"",I17,"")))))) | U17: =IF(B17="hold final","al fallo",IF(T17="",F17&" (piso)",IF(AND(T17>=G17,IF(AND(S17<>"",TRUE()),Q17,IF(AND(Q17<>"",S17=""),O17,IF(AND(O17<>"",Q17=""),M17,IF(AND(M17<>"",O17=""),K17,IF(AND(K17<>"",M17=""),I17,0)))))>=G17),F17&" (piso, progresión nueva)",MIN(G17,T17+IF(E17="s",Reglas!$C$7,Reglas!$C$6))))) -> 3 (piso) | V17: =IF(B17="hold final","",IF(T17="","sin datos",IF(AND(T17>=G17,IF(AND(S17<>"",TRUE()),Q17,IF(AND(Q17<>"",S17=""),O17,IF(AND(O17<>"",Q17=""),M17,IF(AND(M17<>"",O17=""),K17,IF(AND(K17<>"",M17=""),I17,0)))))>=G17),"⬆ SUBIR de progresión",IF(T17>=G17,"techo 1 de 2",IF(T17<F17,"bajo el piso: revisar","en rango"))))) -> sin datos | W17: =IF(AND(I17<>"",H17<>""),IF(I17>=H17,1,0),0)+IF(AND(K17<>"",J17<>""),IF(K17>=J17,1,0),0)+IF(AND(M17<>"",L17<>""),IF(M17>=L17,1,0),0)+IF(AND(O17<>"",N17<>""),IF(O17>=N17,1,0),0)+IF(AND(Q17<>"",P17<>""),IF(Q17>=P17,1,0),0)+IF(AND(S17<>"",R17<>""),IF(S17>=R17,1,0),0) -> 0 | X17: =IF(AND(I17<>"",H17<>""),1,0)+IF(AND(K17<>"",J17<>""),1,0)+IF(AND(M17<>"",L17<>""),1,0)+IF(AND(O17<>"",N17<>""),1,0)+IF(AND(Q17<>"",P17<>""),1,0)+IF(AND(S17<>"",R17<>""),1,0) -> 0 | Y17: =IF(X17=0,"",W17/X17) | Z17: =IF(X17=0,"",(IF(AND(I17<>"",H17<>""),I17-H17,0)+IF(AND(K17<>"",J17<>""),K17-J17,0)+IF(AND(M17<>"",L17<>""),M17-L17,0)+IF(AND(O17<>"",N17<>""),O17-N17,0)+IF(AND(Q17<>"",P17<>""),Q17-P17,0)+IF(AND(S17<>"",R17<>""),S17-R17,0))/X17)
B18: hold final | C18: adv tuck | D18: hold | E18: s | F18: =IF(E18="reps",3,4) -> 4 | G18: =IF(E18="reps",8,12) -> 12 | H18: al fallo | J18: al fallo | L18: al fallo | N18: al fallo | P18: al fallo | R18: al fallo | T18: =IF(S18<>"",S18,IF(Q18<>"",Q18,IF(O18<>"",O18,IF(M18<>"",M18,IF(K18<>"",K18,IF(I18<>"",I18,"")))))) | U18: =IF(B18="hold final","al fallo",IF(T18="",F18&" (piso)",IF(AND(T18>=G18,IF(AND(S18<>"",TRUE()),Q18,IF(AND(Q18<>"",S18=""),O18,IF(AND(O18<>"",Q18=""),M18,IF(AND(M18<>"",O18=""),K18,IF(AND(K18<>"",M18=""),I18,0)))))>=G18),F18&" (piso, progresión nueva)",MIN(G18,T18+IF(E18="s",Reglas!$C$7,Reglas!$C$6))))) -> al fallo | V18: =IF(B18="hold final","",IF(T18="","sin datos",IF(AND(T18>=G18,IF(AND(S18<>"",TRUE()),Q18,IF(AND(Q18<>"",S18=""),O18,IF(AND(O18<>"",Q18=""),M18,IF(AND(M18<>"",O18=""),K18,IF(AND(K18<>"",M18=""),I18,0)))))>=G18),"⬆ SUBIR de progresión",IF(T18>=G18,"techo 1 de 2",IF(T18<F18,"bajo el piso: revisar","en rango")))))

Sheet Vertical
A1: CONQUER · Rutina Mati y Nach
A2: VERTICAL
A3: · Amarillo = lo completás vos (progresión, modo, Real). Gris = predicción.
A4: Ejercicio | B4: Escalón | C4: Progresión | D4: Modo | E4: Tipo | F4: Piso | G4: Techo | H4: S1 prev | I4: S1 real | J4: S2 prev | K4: S2 real | L4: S3 prev | M4: S3 real | N4: S4 prev | O4: S4 real | P4: S5 prev | Q4: S5 real | R4: S6 prev | S4: S6 real | T4: Última | U4: Próximo (S7 prev) | V4: Estado | W4: Aciertos | X4: Sesiones | Y4: % acierto | Z4: Δ medio
A5: HSPU | B5: E1 | C5: paralelas profundas | D5: completa | E5: reps | F5: =IF(E5="reps",3,4) -> 3 | G5: =IF(E5="reps",8,12) -> 8 | H5: =F5 -> 3 | J5: =IF(I5="","",IF(FALSE(),F5,MIN(G5,I5+IF(E5="s",Reglas!$C$7,Reglas!$C$6)))) | L5: =IF(K5="","",IF(AND(K5>=G5,I5>=G5),F5,MIN(G5,K5+IF(E5="s",Reglas!$C$7,Reglas!$C$6)))) | N5: =IF(M5="","",IF(AND(M5>=G5,K5>=G5),F5,MIN(G5,M5+IF(E5="s",Reglas!$C$7,Reglas!$C$6)))) | P5: =IF(O5="","",IF(AND(O5>=G5,M5>=G5),F5,MIN(G5,O5+IF(E5="s",Reglas!$C$7,Reglas!$C$6)))) | R5: =IF(Q5="","",IF(AND(Q5>=G5,O5>=G5),F5,MIN(G5,Q5+IF(E5="s",Reglas!$C$7,Reglas!$C$6)))) | T5: =IF(S5<>"",S5,IF(Q5<>"",Q5,IF(O5<>"",O5,IF(M5<>"",M5,IF(K5<>"",K5,IF(I5<>"",I5,"")))))) | U5: =IF(B5="hold final","al fallo",IF(T5="",F5&" (piso)",IF(AND(T5>=G5,IF(AND(S5<>"",TRUE()),Q5,IF(AND(Q5<>"",S5=""),O5,IF(AND(O5<>"",Q5=""),M5,IF(AND(M5<>"",O5=""),K5,IF(AND(K5<>"",M5=""),I5,0)))))>=G5),F5&" (piso, progresión nueva)",MIN(G5,T5+IF(E5="s",Reglas!$C$7,Reglas!$C$6))))) -> 3 (piso) | V5: =IF(B5="hold final","",IF(T5="","sin datos",IF(AND(T5>=G5,IF(AND(S5<>"",TRUE()),Q5,IF(AND(Q5<>"",S5=""),O5,IF(AND(O5<>"",Q5=""),M5,IF(AND(M5<>"",O5=""),K5,IF(AND(K5<>"",M5=""),I5,0)))))>=G5),"⬆ SUBIR de progresión",IF(T5>=G5,"techo 1 de 2",IF(T5<F5,"bajo el piso: revisar","en rango"))))) -> sin datos | W5: =IF(AND(I5<>"",H5<>""),IF(I5>=H5,1,0),0)+IF(AND(K5<>"",J5<>""),IF(K5>=J5,1,0),0)+IF(AND(M5<>"",L5<>""),IF(M5>=L5,1,0),0)+IF(AND(O5<>"",N5<>""),IF(O5>=N5,1,0),0)+IF(AND(Q5<>"",P5<>""),IF(Q5>=P5,1,0),0)+IF(AND(S5<>"",R5<>""),IF(S5>=R5,1,0),0) -> 0 | X5: =IF(AND(I5<>"",H5<>""),1,0)+IF(AND(K5<>"",J5<>""),1,0)+IF(AND(M5<>"",L5<>""),1,0)+IF(AND(O5<>"",N5<>""),1,0)+IF(AND(Q5<>"",P5<>""),1,0)+IF(AND(S5<>"",R5<>""),1,0) -> 0 | Y5: =IF(X5=0,"",W5/X5) | Z5: =IF(X5=0,"",(IF(AND(I5<>"",H5<>""),I5-H5,0)+IF(AND(K5<>"",J5<>""),K5-J5,0)+IF(AND(M5<>"",L5<>""),M5-L5,0)+IF(AND(O5<>"",N5<>""),O5-N5,0)+IF(AND(Q5<>"",P5<>""),Q5-P5,0)+IF(AND(S5<>"",R5<>""),S5-R5,0))/X5)
B6: E2 | C6: paralelas profundas | D6: negativa | E6: reps | F6: =IF(E6="reps",3,4) -> 3 | G6: =IF(E6="reps",8,12) -> 8 | H6: =F6 -> 3 | J6: =IF(I6="","",IF(FALSE(),F6,MIN(G6,I6+IF(E6="s",Reglas!$C$7,Reglas!$C$6)))) | L6: =IF(K6="","",IF(AND(K6>=G6,I6>=G6),F6,MIN(G6,K6+IF(E6="s",Reglas!$C$7,Reglas!$C$6)))) | N6: =IF(M6="","",IF(AND(M6>=G6,K6>=G6),F6,MIN(G6,M6+IF(E6="s",Reglas!$C$7,Reglas!$C$6)))) | P6: =IF(O6="","",IF(AND(O6>=G6,M6>=G6),F6,MIN(G6,O6+IF(E6="s",Reglas!$C$7,Reglas!$C$6)))) | R6: =IF(Q6="","",IF(AND(Q6>=G6,O6>=G6),F6,MIN(G6,Q6+IF(E6="s",Reglas!$C$7,Reglas!$C$6)))) | T6: =IF(S6<>"",S6,IF(Q6<>"",Q6,IF(O6<>"",O6,IF(M6<>"",M6,IF(K6<>"",K6,IF(I6<>"",I6,"")))))) | U6: =IF(B6="hold final","al fallo",IF(T6="",F6&" (piso)",IF(AND(T6>=G6,IF(AND(S6<>"",TRUE()),Q6,IF(AND(Q6<>"",S6=""),O6,IF(AND(O6<>"",Q6=""),M6,IF(AND(M6<>"",O6=""),K6,IF(AND(K6<>"",M6=""),I6,0)))))>=G6),F6&" (piso, progresión nueva)",MIN(G6,T6+IF(E6="s",Reglas!$C$7,Reglas!$C$6))))) -> 3 (piso) | V6: =IF(B6="hold final","",IF(T6="","sin datos",IF(AND(T6>=G6,IF(AND(S6<>"",TRUE()),Q6,IF(AND(Q6<>"",S6=""),O6,IF(AND(O6<>"",Q6=""),M6,IF(AND(M6<>"",O6=""),K6,IF(AND(K6<>"",M6=""),I6,0)))))>=G6),"⬆ SUBIR de progresión",IF(T6>=G6,"techo 1 de 2",IF(T6<F6,"bajo el piso: revisar","en rango"))))) -> sin datos | W6: =IF(AND(I6<>"",H6<>""),IF(I6>=H6,1,0),0)+IF(AND(K6<>"",J6<>""),IF(K6>=J6,1,0),0)+IF(AND(M6<>"",L6<>""),IF(M6>=L6,1,0),0)+IF(AND(O6<>"",N6<>""),IF(O6>=N6,1,0),0)+IF(AND(Q6<>"",P6<>""),IF(Q6>=P6,1,0),0)+IF(AND(S6<>"",R6<>""),IF(S6>=R6,1,0),0) -> 0 | X6: =IF(AND(I6<>"",H6<>""),1,0)+IF(AND(K6<>"",J6<>""),1,0)+IF(AND(M6<>"",L6<>""),1,0)+IF(AND(O6<>"",N6<>""),1,0)+IF(AND(Q6<>"",P6<>""),1,0)+IF(AND(S6<>"",R6<>""),1,0) -> 0 | Y6: =IF(X6=0,"",W6/X6) | Z6: =IF(X6=0,"",(IF(AND(I6<>"",H6<>""),I6-H6,0)+IF(AND(K6<>"",J6<>""),K6-J6,0)+IF(AND(M6<>"",L6<>""),M6-L6,0)+IF(AND(O6<>"",N6<>""),O6-N6,0)+IF(AND(Q6<>"",P6<>""),Q6-P6,0)+IF(AND(S6<>"",R6<>""),S6-R6,0))/X6)
B7: E3 | C7: wide en piso | D7: completa | E7: reps | F7: =IF(E7="reps",3,4) -> 3 | G7: =IF(E7="reps",8,12) -> 8 | H7: =F7 -> 3 | J7: =IF(I7="","",IF(FALSE(),F7,MIN(G7,I7+IF(E7="s",Reglas!$C$7,Reglas!$C$6)))) | L7: =IF(K7="","",IF(AND(K7>=G7,I7>=G7),F7,MIN(G7,K7+IF(E7="s",Reglas!$C$7,Reglas!$C$6)))) | N7: =IF(M7="","",IF(AND(M7>=G7,K7>=G7),F7,MIN(G7,M7+IF(E7="s",Reglas!$C$7,Reglas!$C$6)))) | P7: =IF(O7="","",IF(AND(O7>=G7,M7>=G7),F7,MIN(G7,O7+IF(E7="s",Reglas!$C$7,Reglas!$C$6)))) | R7: =IF(Q7="","",IF(AND(Q7>=G7,O7>=G7),F7,MIN(G7,Q7+IF(E7="s",Reglas!$C$7,Reglas!$C$6)))) | T7: =IF(S7<>"",S7,IF(Q7<>"",Q7,IF(O7<>"",O7,IF(M7<>"",M7,IF(K7<>"",K7,IF(I7<>"",I7,"")))))) | U7: =IF(B7="hold final","al fallo",IF(T7="",F7&" (piso)",IF(AND(T7>=G7,IF(AND(S7<>"",TRUE()),Q7,IF(AND(Q7<>"",S7=""),O7,IF(AND(O7<>"",Q7=""),M7,IF(AND(M7<>"",O7=""),K7,IF(AND(K7<>"",M7=""),I7,0)))))>=G7),F7&" (piso, progresión nueva)",MIN(G7,T7+IF(E7="s",Reglas!$C$7,Reglas!$C$6))))) -> 3 (piso) | V7: =IF(B7="hold final","",IF(T7="","sin datos",IF(AND(T7>=G7,IF(AND(S7<>"",TRUE()),Q7,IF(AND(Q7<>"",S7=""),O7,IF(AND(O7<>"",Q7=""),M7,IF(AND(M7<>"",O7=""),K7,IF(AND(K7<>"",M7=""),I7,0)))))>=G7),"⬆ SUBIR de progresión",IF(T7>=G7,"techo 1 de 2",IF(T7<F7,"bajo el piso: revisar","en rango"))))) -> sin datos | W7: =IF(AND(I7<>"",H7<>""),IF(I7>=H7,1,0),0)+IF(AND(K7<>"",J7<>""),IF(K7>=J7,1,0),0)+IF(AND(M7<>"",L7<>""),IF(M7>=L7,1,0),0)+IF(AND(O7<>"",N7<>""),IF(O7>=N7,1,0),0)+IF(AND(Q7<>"",P7<>""),IF(Q7>=P7,1,0),0)+IF(AND(S7<>"",R7<>""),IF(S7>=R7,1,0),0) -> 0 | X7: =IF(AND(I7<>"",H7<>""),1,0)+IF(AND(K7<>"",J7<>""),1,0)+IF(AND(M7<>"",L7<>""),1,0)+IF(AND(O7<>"",N7<>""),1,0)+IF(AND(Q7<>"",P7<>""),1,0)+IF(AND(S7<>"",R7<>""),1,0) -> 0 | Y7: =IF(X7=0,"",W7/X7) | Z7: =IF(X7=0,"",(IF(AND(I7<>"",H7<>""),I7-H7,0)+IF(AND(K7<>"",J7<>""),K7-J7,0)+IF(AND(M7<>"",L7<>""),M7-L7,0)+IF(AND(O7<>"",N7<>""),O7-N7,0)+IF(AND(Q7<>"",P7<>""),Q7-P7,0)+IF(AND(S7<>"",R7<>""),S7-R7,0))/X7)
B8: hold final | C8: pike | D8: hold | E8: s | F8: =IF(E8="reps",3,4) -> 4 | G8: =IF(E8="reps",8,12) -> 12 | H8: al fallo | J8: al fallo | L8: al fallo | N8: al fallo | P8: al fallo | R8: al fallo | T8: =IF(S8<>"",S8,IF(Q8<>"",Q8,IF(O8<>"",O8,IF(M8<>"",M8,IF(K8<>"",K8,IF(I8<>"",I8,"")))))) | U8: =IF(B8="hold final","al fallo",IF(T8="",F8&" (piso)",IF(AND(T8>=G8,IF(AND(S8<>"",TRUE()),Q8,IF(AND(Q8<>"",S8=""),O8,IF(AND(O8<>"",Q8=""),M8,IF(AND(M8<>"",O8=""),K8,IF(AND(K8<>"",M8=""),I8,0)))))>=G8),F8&" (piso, progresión nueva)",MIN(G8,T8+IF(E8="s",Reglas!$C$7,Reglas!$C$6))))) -> al fallo | V8: =IF(B8="hold final","",IF(T8="","sin datos",IF(AND(T8>=G8,IF(AND(S8<>"",TRUE()),Q8,IF(AND(Q8<>"",S8=""),O8,IF(AND(O8<>"",Q8=""),M8,IF(AND(M8<>"",O8=""),K8,IF(AND(K8<>"",M8=""),I8,0)))))>=G8),"⬆ SUBIR de progresión",IF(T8>=G8,"techo 1 de 2",IF(T8<F8,"bajo el piso: revisar","en rango")))))
A10: 90° press | B10: E1 | C10: full | D10: completa | E10: reps | F10: =IF(E10="reps",3,4) -> 3 | G10: =IF(E10="reps",8,12) -> 8 | H10: =F10 -> 3 | J10: =IF(I10="","",IF(FALSE(),F10,MIN(G10,I10+IF(E10="s",Reglas!$C$7,Reglas!$C$6)))) | L10: =IF(K10="","",IF(AND(K10>=G10,I10>=G10),F10,MIN(G10,K10+IF(E10="s",Reglas!$C$7,Reglas!$C$6)))) | N10: =IF(M10="","",IF(AND(M10>=G10,K10>=G10),F10,MIN(G10,M10+IF(E10="s",Reglas!$C$7,Reglas!$C$6)))) | P10: =IF(O10="","",IF(AND(O10>=G10,M10>=G10),F10,MIN(G10,O10+IF(E10="s",Reglas!$C$7,Reglas!$C$6)))) | R10: =IF(Q10="","",IF(AND(Q10>=G10,O10>=G10),F10,MIN(G10,Q10+IF(E10="s",Reglas!$C$7,Reglas!$C$6)))) | T10: =IF(S10<>"",S10,IF(Q10<>"",Q10,IF(O10<>"",O10,IF(M10<>"",M10,IF(K10<>"",K10,IF(I10<>"",I10,"")))))) | U10: =IF(B10="hold final","al fallo",IF(T10="",F10&" (piso)",IF(AND(T10>=G10,IF(AND(S10<>"",TRUE()),Q10,IF(AND(Q10<>"",S10=""),O10,IF(AND(O10<>"",Q10=""),M10,IF(AND(M10<>"",O10=""),K10,IF(AND(K10<>"",M10=""),I10,0)))))>=G10),F10&" (piso, progresión nueva)",MIN(G10,T10+IF(E10="s",Reglas!$C$7,Reglas!$C$6))))) -> 3 (piso) | V10: =IF(B10="hold final","",IF(T10="","sin datos",IF(AND(T10>=G10,IF(AND(S10<>"",TRUE()),Q10,IF(AND(Q10<>"",S10=""),O10,IF(AND(O10<>"",Q10=""),M10,IF(AND(M10<>"",O10=""),K10,IF(AND(K10<>"",M10=""),I10,0)))))>=G10),"⬆ SUBIR de progresión",IF(T10>=G10,"techo 1 de 2",IF(T10<F10,"bajo el piso: revisar","en rango"))))) -> sin datos | W10: =IF(AND(I10<>"",H10<>""),IF(I10>=H10,1,0),0)+IF(AND(K10<>"",J10<>""),IF(K10>=J10,1,0),0)+IF(AND(M10<>"",L10<>""),IF(M10>=L10,1,0),0)+IF(AND(O10<>"",N10<>""),IF(O10>=N10,1,0),0)+IF(AND(Q10<>"",P10<>""),IF(Q10>=P10,1,0),0)+IF(AND(S10<>"",R10<>""),IF(S10>=R10,1,0),0) -> 0 | X10: =IF(AND(I10<>"",H10<>""),1,0)+IF(AND(K10<>"",J10<>""),1,0)+IF(AND(M10<>"",L10<>""),1,0)+IF(AND(O10<>"",N10<>""),1,0)+IF(AND(Q10<>"",P10<>""),1,0)+IF(AND(S10<>"",R10<>""),1,0) -> 0 | Y10: =IF(X10=0,"",W10/X10) | Z10: =IF(X10=0,"",(IF(AND(I10<>"",H10<>""),I10-H10,0)+IF(AND(K10<>"",J10<>""),K10-J10,0)+IF(AND(M10<>"",L10<>""),M10-L10,0)+IF(AND(O10<>"",N10<>""),O10-N10,0)+IF(AND(Q10<>"",P10<>""),Q10-P10,0)+IF(AND(S10<>"",R10<>""),S10-R10,0))/X10)
B11: E2 | C11: full | D11: negativa | E11: reps | F11: =IF(E11="reps",3,4) -> 3 | G11: =IF(E11="reps",8,12) -> 8 | H11: =F11 -> 3 | J11: =IF(I11="","",IF(FALSE(),F11,MIN(G11,I11+IF(E11="s",Reglas!$C$7,Reglas!$C$6)))) | L11: =IF(K11="","",IF(AND(K11>=G11,I11>=G11),F11,MIN(G11,K11+IF(E11="s",Reglas!$C$7,Reglas!$C$6)))) | N11: =IF(M11="","",IF(AND(M11>=G11,K11>=G11),F11,MIN(G11,M11+IF(E11="s",Reglas!$C$7,Reglas!$C$6)))) | P11: =IF(O11="","",IF(AND(O11>=G11,M11>=G11),F11,MIN(G11,O11+IF(E11="s",Reglas!$C$7,Reglas!$C$6)))) | R11: =IF(Q11="","",IF(AND(Q11>=G11,O11>=G11),F11,MIN(G11,Q11+IF(E11="s",Reglas!$C$7,Reglas!$C$6)))) | T11: =IF(S11<>"",S11,IF(Q11<>"",Q11,IF(O11<>"",O11,IF(M11<>"",M11,IF(K11<>"",K11,IF(I11<>"",I11,"")))))) | U11: =IF(B11="hold final","al fallo",IF(T11="",F11&" (piso)",IF(AND(T11>=G11,IF(AND(S11<>"",TRUE()),Q11,IF(AND(Q11<>"",S11=""),O11,IF(AND(O11<>"",Q11=""),M11,IF(AND(M11<>"",O11=""),K11,IF(AND(K11<>"",M11=""),I11,0)))))>=G11),F11&" (piso, progresión nueva)",MIN(G11,T11+IF(E11="s",Reglas!$C$7,Reglas!$C$6))))) -> 3 (piso) | V11: =IF(B11="hold final","",IF(T11="","sin datos",IF(AND(T11>=G11,IF(AND(S11<>"",TRUE()),Q11,IF(AND(Q11<>"",S11=""),O11,IF(AND(O11<>"",Q11=""),M11,IF(AND(M11<>"",O11=""),K11,IF(AND(K11<>"",M11=""),I11,0)))))>=G11),"⬆ SUBIR de progresión",IF(T11>=G11,"techo 1 de 2",IF(T11<F11,"bajo el piso: revisar","en rango"))))) -> sin datos | W11: =IF(AND(I11<>"",H11<>""),IF(I11>=H11,1,0),0)+IF(AND(K11<>"",J11<>""),IF(K11>=J11,1,0),0)+IF(AND(M11<>"",L11<>""),IF(M11>=L11,1,0),0)+IF(AND(O11<>"",N11<>""),IF(O11>=N11,1,0),0)+IF(AND(Q11<>"",P11<>""),IF(Q11>=P11,1,0),0)+IF(AND(S11<>"",R11<>""),IF(S11>=R11,1,0),0) -> 0 | X11: =IF(AND(I11<>"",H11<>""),1,0)+IF(AND(K11<>"",J11<>""),1,0)+IF(AND(M11<>"",L11<>""),1,0)+IF(AND(O11<>"",N11<>""),1,0)+IF(AND(Q11<>"",P11<>""),1,0)+IF(AND(S11<>"",R11<>""),1,0) -> 0 | Y11: =IF(X11=0,"",W11/X11) | Z11: =IF(X11=0,"",(IF(AND(I11<>"",H11<>""),I11-H11,0)+IF(AND(K11<>"",J11<>""),K11-J11,0)+IF(AND(M11<>"",L11<>""),M11-L11,0)+IF(AND(O11<>"",N11<>""),O11-N11,0)+IF(AND(Q11<>"",P11<>""),Q11-P11,0)+IF(AND(S11<>"",R11<>""),S11-R11,0))/X11)
